Workbook

Sheet Fase de Grupos
A1: Jogo # | B1: Data | C1: Horário (BRT) | D1: Grupo | E1: Seleção 1 | F1: Gols 1 | G1: x | H1: Gols 2 | I1: Seleção 2 | J1: Cidade/Estádio
A2: 1 | B2: 11/06 | C2: 16:00 | D2: A | E2: México | F2: 2 | G2: x | H2: 0 | I2: África do Sul | J2: Cidade do México
A3: 2 | B3: 11/06 | C3: 23:00 | D3: A | E3: Coreia do Sul | F3: 2 | G3: x | H3: 1 | I3: República Tcheca | J3: Guadalajara
A4: 3 | B4: 12/06 | C4: 16:00 | D4: B | E4: Canadá | F4: 1 | G4: x | H4: 1 | I4: Bósnia e Herzegovina | J4: Toronto
A5: 4 | B5: 12/06 | C5: 22:00 | D5: D | E5: EUA | F5: 4 | G5: x | H5: 1 | I5: Paraguai | J5: Los Angeles
A6: 5 | B6: 13/06 | C6: 16:00 | D6: B | E6: Catar | F6: 1 | G6: x | H6: 1 | I6: Suíça | J6: San Francisco
A7: 6 | B7: 13/06 | C7: 19:00 | D7: C | E7: Brasil | F7: 1 | G7: x | H7: 1 | I7: Marrocos | J7: Nova York/NJ
A8: 7 | B8: 13/06 | C8: 22:00 | D8: C | E8: Haiti | F8: 0 | G8: x | H8: 1 | I8: Escócia | J8: Boston
A9: 8 | B9: 14/06 | C9: 01:00 | D9: D | E9: Austrália | F9: 2 | G9: x | H9: 0 | I9: Turquia | J9: Vancouver
A10: 9 | B10: 14/06 | C10: 14:00 | D10: E | E10: Alemanha | F10: 7 | G10: x | H10: 1 | I10: Curaçao | J10: Houston
A11: 10 | B11: 14/06 | C11: 17:00 | D11: F | E11: Holanda | F11: 2 | G11: x | H11: 2 | I11: Japão | J11: Dallas
A12: 11 | B12: 14/06 | C12: 20:00 | D12: E | E12: Costa do Marfim | F12: 1 | G12: x | H12: 0 | I12: Equador | J12: Filadélfia
A13: 12 | B13: 14/06 | C13: 23:00 | D13: F | E13: Suécia | F13: 5 | G13: x | H13: 1 | I13: Tunísia | J13: Monterrey
... A73: 72 | B73: 27/06 | C73: 18:00 | D73: K | E73: RD Congo | F73: 3 | G73: x | H73: 1 | I73: Uzbequistão | J73: Atlanta

Sheet Classificação
A1: Grupo A
A2: Pos | B2: Seleção | C2: J | D2: V | E2: E | F2: D | G2: GP | H2: GC | I2: SG | J2: PTS
A3: 1 | B3: México | C3: =SUMPRODUCT(('Fase de Grupos'!$E$2:$E$73=$B3)*ISNUMBER('Fase de Grupos'!$F$2:$F$73)*ISNUMBER('Fase de Grupos'!$H$2:$H$73))+SUMPRODUCT(('Fase de Grupos'!$I$2:$I$73=$B3)*ISNUMBER('Fase de Grupos'!$F$2:$F$73)*ISNUMBER('Fase de Grupos'!$H$2:$H$73)) -> 3 | D3: =SUMPRODUCT(('Fase de Grupos'!$E$2:$E$73=$B3)*ISNUMBER('Fase de Grupos'!$F$2:$F$73)*ISNUMBER('Fase de Grupos'!$H$2:$H$73)*('Fase de Grupos'!$F$2:$F$73>'Fase de Grupos'!$H$2:$H$73))+SUMPRODUCT(('Fase de Grupos'!$I$2:$I$73=$B3)*ISNUMBER('Fase de Grupos'!$F$2:$F$73)*ISNUMBER('Fase de Grupos'!$H$2:$H$73)*('Fase de Grupos'!$H$2:$H$73>'Fase de Grupos'!$F$2:$F$73)) -> 3 | E3: =SUMPRODUCT(('Fase de Grupos'!$E$2:$E$73=$B3)*ISNUMBER('Fase de Grupos'!$F$2:$F$73)*ISNUMBER('Fase de Grupos'!$H$2:$H$73)*('Fase de Grupos'!$F$2:$F$73='Fase de Grupos'!$H$2:$H$73))+SUMPRODUCT(('Fase de Grupos'!$I$2:$I$73=$B3)*ISNUMBER('Fase de Grupos'!$F$2:$F$73)*ISNUMBER('Fase de Grupos'!$H$2:$H$73)*('Fase de Grupos'!$F$2:$F$73='Fase de Grupos'!$H$2:$H$73)) -> 0 | F3: =SUMPRODUCT(('Fase de Grupos'!$E$2:$E$73=$B3)*ISNUMBER('Fase de Grupos'!$F$2:$F$73)*ISNUMBER('Fase de Grupos'!$H$2:$H$73)*('Fase de Grupos'!$F$2:$F$73<'Fase de Grupos'!$H$2:$H$73))+SUMPRODUCT(('Fase de Grupos'!$I$2:$I$73=$B3)*ISNUMBER('Fase de Grupos'!$F$2:$F$73)*ISNUMBER('Fase de Grupos'!$H$2:$H$73)*('Fase de Grupos'!$H$2:$H$73<'Fase de Grupos'!$F$2:$F$73)) -> 0 | G3: =SUMPRODUCT(('Fase de Grupos'!$E$2:$E$73=$B3)*ISNUMBER('Fase de Grupos'!$F$2:$F$73)*ISNUMBER('Fase de Grupos'!$H$2:$H$73)*'Fase de Grupos'!$F$2:$F$73)+SUMPRODUCT(('Fase de Grupos'!$I$2:$I$73=$B3)*ISNUMBER('Fase de Grupos'!$F$2:$F$73)*ISNUMBER('Fase de Grupos'!$H$2:$H$73)*'Fase de Grupos'!$H$2:$H$73) -> 6 | H3: =SUMPRODUCT(('Fase de Grupos'!$E$2:$E$73=$B3)*ISNUMBER('Fase de Grupos'!$F$2:$F$73)*ISNUMBER('Fase de Grupos'!$H$2:$H$73)*'Fase de Grupos'!$H$2:$H$73)+SUMPRODUCT(('Fase de Grupos'!$I$2:$I$73=$B3)*ISNUMBER('Fase de Grupos'!$F$2:$F$73)*ISNUMBER('Fase de Grupos'!$H$2:$H$73)*'Fase de Grupos'!$F$2:$F$73) -> 0 | I3: =G3-H3 -> 6 | J3: =D3*3+E3 -> 9
A4: 2 | B4: Coreia do Sul | C4: =SUMPRODUCT(('Fase de Grupos'!$E$2:$E$73=$B4)*ISNUMBER('Fase de Grupos'!$F$2:$F$73)*ISNUMBER('Fase de Grupos'!$H$2:$H$73))+SUMPRODUCT(('Fase de Grupos'!$I$2:$I$73=$B4)*ISNUMBER('Fase de Grupos'!$F$2:$F$73)*ISNUMBER('Fase de Grupos'!$H$2:$H$73)) -> 3 | D4: =SUMPRODUCT(('Fase de Grupos'!$E$2:$E$73=$B4)*ISNUMBER('Fase de Grupos'!$F$2:$F$73)*ISNUMBER('Fase de Grupos'!$H$2:$H$73)*('Fase de Grupos'!$F$2:$F$73>'Fase de Grupos'!$H$2:$H$73))+SUMPRODUCT(('Fase de Grupos'!$I$2:$I$73=$B4)*ISNUMBER('Fase de Grupos'!$F$2:$F$73)*ISNUMBER('Fase de Grupos'!$H$2:$H$73)*('Fase de Grupos'!$H$2:$H$73>'Fase de Grupos'!$F$2:$F$73)) -> 1 | E4: =SUMPRODUCT(('Fase de Grupos'!$E$2:$E$73=$B4)*ISNUMBER('Fase de Grupos'!$F$2:$F$73)*ISNUMBER('Fase de Grupos'!$H$2:$H$73)*('Fase de Grupos'!$F$2:$F$73='Fase de Grupos'!$H$2:$H$73))+SUMPRODUCT(('Fase de Grupos'!$I$2:$I$73=$B4)*ISNUMBER('Fase de Grupos'!$F$2:$F$73)*ISNUMBER('Fase de Grupos'!$H$2:$H$73)*('Fase de Grupos'!$F$2:$F$73='Fase de Grupos'!$H$2:$H$73)) -> 0 | F4: =SUMPRODUCT(('Fase de Grupos'!$E$2:$E$73=$B4)*ISNUMBER('Fase de Grupos'!$F$2:$F$73)*ISNUMBER('Fase de Grupos'!$H$2:$H$73)*('Fase de Grupos'!$F$2:$F$73<'Fase de Grupos'!$H$2:$H$73))+SUMPRODUCT(('Fase de Grupos'!$I$2:$I$73=$B4)*ISNUMBER('Fase de Grupos'!$F$2:$F$73)*ISNUMBER('Fase de Grupos'!$H$2:$H$73)*('Fase de Grupos'!$H$2:$H$73<'Fase de Grupos'!$F$2:$F$73)) -> 2 | G4: =SUMPRODUCT(('Fase de Grupos'!$E$2:$E$73=$B4)*ISNUMBER('Fase de Grupos'!$F$2:$F$73)*ISNUMBER('Fase de Grupos'!$H$2:$H$73)*'Fase de Grupos'!$F$2:$F$73)+SUMPRODUCT(('Fase de Grupos'!$I$2:$I$73=$B4)*ISNUMBER('Fase de Grupos'!$F$2:$F$73)*ISNUMBER('Fase de Grupos'!$H$2:$H$73)*'Fase de Grupos'!$H$2:$H$73) -> 2 | H4: =SUMPRODUCT(('Fase de Grupos'!$E$2:$E$73=$B4)*ISNUMBER('Fase de Grupos'!$F$2:$F$73)*ISNUMBER('Fase de Grupos'!$H$2:$H$73)*'Fase de Grupos'!$H$2:$H$73)+SUMPRODUCT(('Fase de Grupos'!$I$2:$I$73=$B4)*ISNUMBER('Fase de Grupos'!$F$2:$F$73)*ISNUMBER('Fase de Grupos'!$H$2:$H$73)*'Fase de Grupos'!$F$2:$F$73) -> 3 | I4: =G4-H4 -> -1 | J4: =D4*3+E4 -> 3
A5: 3 | B5: África do Sul | C5: =SUMPRODUCT(('Fase de Grupos'!$E$2:$E$73=$B5)*ISNUMBER('Fase de Grupos'!$F$2:$F$73)*ISNUMBER('Fase de Grupos'!$H$2:$H$73))+SUMPRODUCT(('Fase de Grupos'!$I$2:$I$73=$B5)*ISNUMBER('Fase de Grupos'!$F$2:$F$73)*ISNUMBER('Fase de Grupos'!$H$2:$H$73)) -> 3 | D5: =SUMPRODUCT(('Fase de Grupos'!$E$2:$E$73=$B5)*ISNUMBER('Fase de Grupos'!$F$2:$F$73)*ISNUMBER('Fase de Grupos'!$H$2:$H$73)*('Fase de Grupos'!$F$2:$F$73>'Fase de Grupos'!$H$2:$H$73))+SUMPRODUCT(('Fase de Grupos'!$I$2:$I$73=$B5)*ISNUMBER('Fase de Grupos'!$F$2:$F$73)*ISNUMBER('Fase de Grupos'!$H$2:$H$73)*('Fase de Grupos'!$H$2:$H$73>'Fase de Grupos'!$F$2:$F$73)) -> 1 | E5: =SUMPRODUCT(('Fase de Grupos'!$E$2:$E$73=$B5)*ISNUMBER('Fase de Grupos'!$F$2:$F$73)*ISNUMBER('Fase de Grupos'!$H$2:$H$73)*('Fase de Grupos'!$F$2:$F$73='Fase de Grupos'!$H$2:$H$73))+SUMPRODUCT(('Fase de Grupos'!$I$2:$I$73=$B5)*ISNUMBER('Fase de Grupos'!$F$2:$F$73)*ISNUMBER('Fase de Grupos'!$H$2:$H$73)*('Fase de Grupos'!$F$2:$F$73='Fase de Grupos'!$H$2:$H$73)) -> 1 | F5: =SUMPRODUCT(('Fase de Grupos'!$E$2:$E$73=$B5)*ISNUMBER('Fase de Grupos'!$F$2:$F$73)*ISNUMBER('Fase de Grupos'!$H$2:$H$73)*('Fase de Grupos'!$F$2:$F$73<'Fase de Grupos'!$H$2:$H$73))+SUMPRODUCT(('Fase de Grupos'!$I$2:$I$73=$B5)*ISNUMBER('Fase de Grupos'!$F$2:$F$73)*ISNUMBER('Fase de Grupos'!$H$2:$H$73)*('Fase de Grupos'!$H$2:$H$73<'Fase de Grupos'!$F$2:$F$73)) -> 1 | G5: =SUMPRODUCT(('Fase de Grupos'!$E$2:$E$73=$B5)*ISNUMBER('Fase de Grupos'!$F$2:$F$73)*ISNUMBER('Fase de Grupos'!$H$2:$H$73)*'Fase de Grupos'!$F$2:$F$73)+SUMPRODUCT(('Fase de Grupos'!$I$2:$I$73=$B5)*ISNUMBER('Fase de Grupos'!$F$2:$F$73)*ISNUMBER('Fase de Grupos'!$H$2:$H$73)*'Fase de Grupos'!$H$2:$H$73) -> 2 | H5: =SUMPRODUCT(('Fase de Grupos'!$E$2:$E$73=$B5)*ISNUMBER('Fase de Grupos'!$F$2:$F$73)*ISNUMBER('Fase de Grupos'!$H$2:$H$73)*'Fase de Grupos'!$H$2:$H$73)+SUMPRODUCT(('Fase de Grupos'!$I$2:$I$73=$B5)*ISNUMBER('Fase de Grupos'!$F$2:$F$73)*ISNUMBER('Fase de Grupos'!$H$2:$H$73)*'Fase de Grupos'!$F$2:$F$73) -> 3 | I5: =G5-H5 -> -1 | J5: =D5*3+E5 -> 4
A6: 4 | B6: República Tcheca | C6: =SUMPRODUCT(('Fase de Grupos'!$E$2:$E$73=$B6)*ISNUMBER('Fase de Grupos'!$F$2:$F$73)*ISNUMBER('Fase de Grupos'!$H$2:$H$73))+SUMPRODUCT(('Fase de Grupos'!$I$2:$I$73=$B6)*ISNUMBER('Fase de Grupos'!$F$2:$F$73)*ISNUMBER('Fase de Grupos'!$H$2:$H$73)) -> 3 | D6: =SUMPRODUCT(('Fase de Grupos'!$E$2:$E$73=$B6)*ISNUMBER('Fase de Grupos'!$F$2:$F$73)*ISNUMBER('Fase de Grupos'!$H$2:$H$73)*('Fase de Grupos'!$F$2:$F$73>'Fase de Grupos'!$H$2:$H$73))+SUMPRODUCT(('Fase de Grupos'!$I$2:$I$73=$B6)*ISNUMBER('Fase de Grupos'!$F$2:$F$73)*ISNUMBER('Fase de Grupos'!$H$2:$H$73)*('Fase de Grupos'!$H$2:$H$73>'Fase de Grupos'!$F$2:$F$73)) -> 0 | E6: =SUMPRODUCT(('Fase de Grupos'!$E$2:$E$73=$B6)*ISNUMBER('Fase de Grupos'!$F$2:$F$73)*ISNUMBER('Fase de Grupos'!$H$2:$H$73)*('Fase de Grupos'!$F$2:$F$73='Fase de Grupos'!$H$2:$H$73))+SUMPRODUCT(('Fase de Grupos'!$I$2:$I$73=$B6)*ISNUMBER('Fase de Grupos'!$F$2:$F$73)*ISNUMBER('Fase de Grupos'!$H$2:$H$73)*('Fase de Grupos'!$F$2:$F$73='Fase de Grupos'!$H$2:$H$73)) -> 1 | F6: =SUMPRODUCT(('Fase de Grupos'!$E$2:$E$73=$B6)*ISNUMBER('Fase de Grupos'!$F$2:$F$73)*ISNUMBER('Fase de Grupos'!$H$2:$H$73)*('Fase de Grupos'!$F$2:$F$73<'Fase de Grupos'!$H$2:$H$73))+SUMPRODUCT(('Fase de Grupos'!$I$2:$I$73=$B6)*ISNUMBER('Fase de Grupos'!$F$2:$F$73)*ISNUMBER('Fase de Grupos'!$H$2:$H$73)*('Fase de Grupos'!$H$2:$H$73<'Fase de Grupos'!$F$2:$F$73)) -> 2 | G6: =SUMPRODUCT(('Fase de Grupos'!$E$2:$E$73=$B6)*ISNUMBER('Fase de Grupos'!$F$2:$F$73)*ISNUMBER('Fase de Grupos'!$H$2:$H$73)*'Fase de Grupos'!$F$2:$F$73)+SUMPRODUCT(('Fase de Grupos'!$I$2:$I$73=$B6)*ISNUMBER('Fase de Grupos'!$F$2:$F$73)*ISNUMBER('Fase de Grupos'!$H$2:$H$73)*'Fase de Grupos'!$H$2:$H$73) -> 2 | H6: =SUMPRODUCT(('Fase de Grupos'!$E$2:$E$73=$B6)*ISNUMBER('Fase de Grupos'!$F$2:$F$73)*ISNUMBER('Fase de Grupos'!$H$2:$H$73)*'Fase de Grupos'!$H$2:$H$73)+SUMPRODUCT(('Fase de Grupos'!$I$2:$I$73=$B6)*ISNUMBER('Fase de Grupos'!$F$2:$F$73)*ISNUMBER('Fase de Grupos'!$H$2:$H$73)*'Fase de Grupos'!$F$2:$F$73) -> 6 | I6: =G6-H6 -> -4 | J6: =D6*3+E6 -> 1
A8: Grupo B
A9: Pos | B9: Seleção | C9: J | D9: V | E9: E | F9: D | G9: GP | H9: GC | I9: SG | J9: PTS
A10: 1 | B10: Canadá | C10: =SUMPRODUCT(('Fase de Grupos'!$E$2:$E$73=$B10)*ISNUMBER('Fase de Grupos'!$F$2:$F$73)*ISNUMBER('Fase de Grupos'!$H$2:$H$73))+SUMPRODUCT(('Fase de Grupos'!$I$2:$I$73=$B10)*ISNUMBER('Fase de Grupos'!$F$2:$F$73)*ISNUMBER('Fase de Grupos'!$H$2:$H$73)) -> 3 | D10: =SUMPRODUCT(('Fase de Grupos'!$E$2:$E$73=$B10)*ISNUMBER('Fase de Grupos'!$F$2:$F$73)*ISNUMBER('Fase de Grupos'!$H$2:$H$73)*('Fase de Grupos'!$F$2:$F$73>'Fase de Grupos'!$H$2:$H$73))+SUMPRODUCT(('Fase de Grupos'!$I$2:$I$73=$B10)*ISNUMBER('Fase de Grupos'!$F$2:$F$73)*ISNUMBER('Fase de Grupos'!$H$2:$H$73)*('Fase de Grupos'!$H$2:$H$73>'Fase de Grupos'!$F$2:$F$73)) -> 1 | E10: =SUMPRODUCT(('Fase de Grupos'!$E$2:$E$73=$B10)*ISNUMBER('Fase de Grupos'!$F$2:$F$73)*ISNUMBER('Fase de Grupos'!$H$2:$H$73)*('Fase de Grupos'!$F$2:$F$73='Fase de Grupos'!$H$2:$H$73))+SUMPRODUCT(('Fase de Grupos'!$I$2:$I$73=$B10)*ISNUMBER('Fase de Grupos'!$F$2:$F$73)*ISNUMBER('Fase de Grupos'!$H$2:$H$73)*('Fase de Grupos'!$F$2:$F$73='Fase de Grupos'!$H$2:$H$73)) -> 1 | F10: =SUMPRODUCT(('Fase de Grupos'!$E$2:$E$73=$B10)*ISNUMBER('Fase de Grupos'!$F$2:$F$73)*ISNUMBER('Fase de Grupos'!$H$2:$H$73)*('Fase de Grupos'!$F$2:$F$73<'Fase de Grupos'!$H$2:$H$73))+SUMPRODUCT(('Fase de Grupos'!$I$2:$I$73=$B10)*ISNUMBER('Fase de Grupos'!$F$2:$F$73)*ISNUMBER('Fase de Grupos'!$H$2:$H$73)*('Fase de Grupos'!$H$2:$H$73<'Fase de Grupos'!$F$2:$F$73)) -> 1 | G10: =SUMPRODUCT(('Fase de Grupos'!$E$2:$E$73=$B10)*ISNUMBER('Fase de Grupos'!$F$2:$F$73)*ISNUMBER('Fase de Grupos'!$H$2:$H$73)*'Fase de Grupos'!$F$2:$F$73)+SUMPRODUCT(('Fase de Grupos'!$I$2:$I$73=$B10)*ISNUMBER('Fase de Grupos'!$F$2:$F$73)*ISNUMBER('Fase de Grupos'!$H$2:$H$73)*'Fase de Grupos'!$H$2:$H$73) -> 8 | H10: =SUMPRODUCT(('Fase de Grupos'!$E$2:$E$73=$B10)*ISNUMBER('Fase de Grupos'!$F$2:$F$73)*ISNUMBER('Fase de Grupos'!$H$2:$H$73)*'Fase de Grupos'!$H$2:$H$73)+SUMPRODUCT(('Fase de Grupos'!$I$2:$I$73=$B10)*ISNUMBER('Fase de Grupos'!$F$2:$F$73)*ISNUMBER('Fase de Grupos'!$H$2:$H$73)*'Fase de Grupos'!$F$2:$F$73) -> 3 | I10: =G10-H10 -> 5 | J10: =D10*3+E10 -> 4
A11: 2 | B11: Suíça | C11: =SUMPRODUCT(('Fase de Grupos'!$E$2:$E$73=$B11)*ISNUMBER('Fase de Grupos'!$F$2:$F$73)*ISNUMBER('Fase de Grupos'!$H$2:$H$73))+SUMPRODUCT(('Fase de Grupos'!$I$2:$I$73=$B11)*ISNUMBER('Fase de Grupos'!$F$2:$F$73)*ISNUMBER('Fase de Grupos'!$H$2:$H$73)) -> 3 | D11: =SUMPRODUCT(('Fase de Grupos'!$E$2:$E$73=$B11)*ISNUMBER('Fase de Grupos'!$F$2:$F$73)*ISNUMBER('Fase de Grupos'!$H$2:$H$73)*('Fase de Grupos'!$F$2:$F$73>'Fase de Grupos'!$H$2:$H$73))+SUMPRODUCT(('Fase de Grupos'!$I$2:$I$73=$B11)*ISNUMBER('Fase de Grupos'!$F$2:$F$73)*ISNUMBER('Fase de Grupos'!$H$2:$H$73)*('Fase de Grupos'!$H$2:$H$73>'Fase de Grupos'!$F$2:$F$73)) -> 2 | E11: =SUMPRODUCT(('Fase de Grupos'!$E$2:$E$73=$B11)*ISNUMBER('Fase de Grupos'!$F$2:$F$73)*ISNUMBER('Fase de Grupos'!$H$2:$H$73)*('Fase de Grupos'!$F$2:$F$73='Fase de Grupos'!$H$2:$H$73))+SUMPRODUCT(('Fase de Grupos'!$I$2:$I$73=$B11)*ISNUMBER('Fase de Grupos'!$F$2:$F$73)*ISNUMBER('Fase de Grupos'!$H$2:$H$73)*('Fase de Grupos'!$F$2:$F$73='Fase de Grupos'!$H$2:$H$73)) -> 1 | F11: =SUMPRODUCT(('Fase de Grupos'!$E$2:$E$73=$B11)*ISNUMBER('Fase de Grupos'!$F$2:$F$73)*ISNUMBER('Fase de Grupos'!$H$2:$H$73)*('Fase de Grupos'!$F$2:$F$73<'Fase de Grupos'!$H$2:$H$73))+SUMPRODUCT(('Fase de Grupos'!$I$2:$I$73=$B11)*ISNUMBER('Fase de Grupos'!$F$2:$F$73)*ISNUMBER('Fase de Grupos'!$H$2:$H$73)*('Fase de Grupos'!$H$2:$H$73<'Fase de Grupos'!$F$2:$F$73)) -> 0 | G11: =SUMPRODUCT(('Fase de Grupos'!$E$2:$E$73=$B11)*ISNUMBER('Fase de Grupos'!$F$2:$F$73)*ISNUMBER('Fase de Grupos'!$H$2:$H$73)*'Fase de Grupos'!$F$2:$F$73)+SUMPRODUCT(('Fase de Grupos'!$I$2:$I$73=$B11)*ISNUMBER('Fase de Grupos'!$F$2:$F$73)*ISNUMBER('Fase de Grupos'!$H$2:$H$73)*'Fase de Grupos'!$H$2:$H$73) -> 7 | H11: =SUMPRODUCT(('Fase de Grupos'!$E$2:$E$73=$B11)*ISNUMBER('Fase de Grupos'!$F$2:$F$73)*ISNUMBER('Fase de Grupos'!$H$2:$H$73)*'Fase de Grupos'!$H$2:$H$73)+SUMPRODUCT(('Fase de Grupos'!$I$2:$I$73=$B11)*ISNUMBER('Fase de Grupos'!$F$2:$F$73)*ISNUMBER('Fase de Grupos'!$H$2:$H$73)*'Fase de Grupos'!$F$2:$F$73) -> 3 | I11: =G11-H11 -> 4 | J11: =D11*3+E11 -> 7
A12: 3 | B12: Catar | C12: =SUMPRODUCT(('Fase de Grupos'!$E$2:$E$73=$B12)*ISNUMBER('Fase de Grupos'!$F$2:$F$73)*ISNUMBER('Fase de Grupos'!$H$2:$H$73))+SUMPRODUCT(('Fase de Grupos'!$I$2:$I$73=$B12)*ISNUMBER('Fase de Grupos'!$F$2:$F$73)*ISNUMBER('Fase de Grupos'!$H$2:$H$73)) -> 3 | D12: =SUMPRODUCT(('Fase de Grupos'!$E$2:$E$73=$B12)*ISNUMBER('Fase de Grupos'!$F$2:$F$73)*ISNUMBER('Fase de Grupos'!$H$2:$H$73)*('Fase de Grupos'!$F$2:$F$73>'Fase de Grupos'!$H$2:$H$73))+SUMPRODUCT(('Fase de Grupos'!$I$2:$I$73=$B12)*ISNUMBER('Fase de Grupos'!$F$2:$F$73)*ISNUMBER('Fase de Grupos'!$H$2:$H$73)*('Fase de Grupos'!$H$2:$H$73>'Fase de Grupos'!$F$2:$F$73)) -> 0 | E12: =SUMPRODUCT(('Fase de Grupos'!$E$2:$E$73=$B12)*ISNUMBER('Fase de Grupos'!$F$2:$F$73)*ISNUMBER('Fase de Grupos'!$H$2:$H$73)*('Fase de Grupos'!$F$2:$F$73='Fase de Grupos'!$H$2:$H$73))+SUMPRODUCT(('Fase de Grupos'!$I$2:$I$73=$B12)*ISNUMBER('Fase de Grupos'!$F$2:$F$73)*ISNUMBER('Fase de Grupos'!$H$2:$H$73)*('Fase de Grupos'!$F$2:$F$73='Fase de Grupos'!$H$2:$H$73)) -> 1 | F12: =SUMPRODUCT(('Fase de Grupos'!$E$2:$E$73=$B12)*ISNUMBER('Fase de Grupos'!$F$2:$F$73)*ISNUMBER('Fase de Grupos'!$H$2:$H$73)*('Fase de Grupos'!$F$2:$F$73<'Fase de Grupos'!$H$2:$H$73))+SUMPRODUCT(('Fase de Grupos'!$I$2:$I$73=$B12)*ISNUMBER('Fase de Grupos'!$F$2:$F$73)*ISNUMBER('Fase de Grupos'!$H$2:$H$73)*('Fase de Grupos'!$H$2:$H$73<'Fase de Grupos'!$F$2:$F$73)) -> 2 | G12: =SUMPRODUCT(('Fase de Grupos'!$E$2:$E$73=$B12)*ISNUMBER('Fase de Grupos'!$F$2:$F$73)*ISNUMBER('Fase de Grupos'!$H$2:$H$73)*'Fase de Grupos'!$F$2:$F$73)+SUMPRODUCT(('Fase de Grupos'!$I$2:$I$73=$B12)*ISNUMBER('Fase de Grupos'!$F$2:$F$73)*ISNUMBER('Fase de Grupos'!$H$2:$H$73)*'Fase de Grupos'!$H$2:$H$73) -> 2 | H12: =SUMPRODUCT(('Fase de Grupos'!$E$2:$E$73=$B12)*ISNUMBER('Fase de Grupos'!$F$2:$F$73)*ISNUMBER('Fase de Grupos'!$H$2:$H$73)*'Fase de Grupos'!$H$2:$H$73)+SUMPRODUCT(('Fase de Grupos'!$I$2:$I$73=$B12)*ISNUMBER('Fase de Grupos'!$F$2:$F$73)*ISNUMBER('Fase de Grupos'!$H$2:$H$73)*'Fase de Grupos'!$F$2:$F$73) -> 10 | I12: =G12-H12 -> -8 | J12: =D12*3+E12 -> 1
A13: 4 | B13: Bósnia e Herzegovina | C13: =SUMPRODUCT(('Fase de Grupos'!$E$2:$E$73=$B13)*ISNUMBER('Fase de Grupos'!$F$2:$F$73)*ISNUMBER('Fase de Grupos'!$H$2:$H$73))+SUMPRODUCT(('Fase de Grupos'!$I$2:$I$73=$B13)*ISNUMBER('Fase de Grupos'!$F$2:$F$73)*ISNUMBER('Fase de Grupos'!$H$2:$H$73)) -> 3 | D13: =SUMPRODUCT(('Fase de Grupos'!$E$2:$E$73=$B13)*ISNUMBER('Fase de Grupos'!$F$2:$F$73)*ISNUMBER('Fase de Grupos'!$H$2:$H$73)*('Fase de Grupos'!$F$2:$F$73>'Fase de Grupos'!$H$2:$H$73))+SUMPRODUCT(('Fase de Grupos'!$I$2:$I$73=$B13)*ISNUMBER('Fase de Grupos'!$F$2:$F$73)*ISNUMBER('Fase de Grupos'!$H$2:$H$73)*('Fase de Grupos'!$H$2:$H$73>'Fase de Grupos'!$F$2:$F$73)) -> 1 | E13: =SUMPRODUCT(('Fase de Grupos'!$E$2:$E$73=$B13)*ISNUMBER('Fase de Grupos'!$F$2:$F$73)*ISNUMBER('Fase de Grupos'!$H$2:$H$73)*('Fase de Grupos'!$F$2:$F$73='Fase de Grupos'!$H$2:$H$73))+SUMPRODUCT(('Fase de Grupos'!$I$2:$I$73=$B13)*ISNUMBER('Fase de Grupos'!$F$2:$F$73)*ISNUMBER('Fase de Grupos'!$H$2:$H$73)*('Fase de Grupos'!$F$2:$F$73='Fase de Grupos'!$H$2:$H$73)) -> 1 | F13: =SUMPRODUCT(('Fase de Grupos'!$E$2:$E$73=$B13)*ISNUMBER('Fase de Grupos'!$F$2:$F$73)*ISNUMBER('Fase de Grupos'!$H$2:$H$73)*('Fase de Grupos'!$F$2:$F$73<'Fase de Grupos'!$H$2:$H$73))+SUMPRODUCT(('Fase de Grupos'!$I$2:$I$73=$B13)*ISNUMBER('Fase de Grupos'!$F$2:$F$73)*ISNUMBER('Fase de Grupos'!$H$2:$H$73)*('Fase de Grupos'!$H$2:$H$73<'Fase de Grupos'!$F$2:$F$73)) -> 1 | G13: =SUMPRODUCT(('Fase de Grupos'!$E$2:$E$73=$B13)*ISNUMBER('Fase de Grupos'!$F$2:$F$73)*ISNUMBER('Fase de Grupos'!$H$2:$H$73)*'Fase de Grupos'!$F$2:$F$73)+SUMPRODUCT(('Fase de Grupos'!$I$2:$I$73=$B13)*ISNUMBER('Fase de Grupos'!$F$2:$F$73)*ISNUMBER('Fase de Grupos'!$H$2:$H$73)*'Fase de Grupos'!$H$2:$H$73) -> 5 | H13: =SUMPRODUCT(('Fase de Grupos'!$E$2:$E$73=$B13)*ISNUMBER('Fase de Grupos'!$F$2:$F$73)*ISNUMBER('Fase de Grupos'!$H$2:$H$73)*'Fase de Grupos'!$H$2:$H$73)+SUMPRODUCT(('Fase de Grupos'!$I$2:$I$73=$B13)*ISNUMBER('Fase de Grupos'!$F$2:$F$73)*ISNUMBER('Fase de Grupos'!$H$2:$H$73)*'Fase de Grupos'!$F$2:$F$73) -> 6 | I13: =G13-H13 -> -1 | J13: =D13*3+E13 -> 4
A15: Grupo C
A16: Pos | B16: Seleção | C16: J | D16: V | E16: E | F16: D | G16: GP | H16: GC | I16: SG | J16: PTS
A17: 1 | B17: Brasil | C17: =SUMPRODUCT(('Fase de Grupos'!$E$2:$E$73=$B17)*ISNUMBER('Fase de Grupos'!$F$2:$F$73)*ISNUMBER('Fase de Grupos'!$H$2:$H$73))+SUMPRODUCT(('Fase de Grupos'!$I$2:$I$73=$B17)*ISNUMBER('Fase de Grupos'!$F$2:$F$73)*ISNUMBER('Fase de Grupos'!$H$2:$H$73)) -> 3 | D17: =SUMPRODUCT(('Fase de Grupos'!$E$2:$E$73=$B17)*ISNUMBER('Fase de Grupos'!$F$2:$F$73)*ISNUMBER('Fase de Grupos'!$H$2:$H$73)*('Fase de Grupos'!$F$2:$F$73>'Fase de Grupos'!$H$2:$H$73))+SUMPRODUCT(('Fase de Grupos'!$I$2:$I$73=$B17)*ISNUMBER('Fase de Grupos'!$F$2:$F$73)*ISNUMBER('Fase de Grupos'!$H$2:$H$73)*('Fase de Grupos'!$H$2:$H$73>'Fase de Grupos'!$F$2:$F$73)) -> 2 | E17: =SUMPRODUCT(('Fase de Grupos'!$E$2:$E$73=$B17)*ISNUMBER('Fase de Grupos'!$F$2:$F$73)*ISNUMBER('Fase de Grupos'!$H$2:$H$73)*('Fase de Grupos'!$F$2:$F$73='Fase de Grupos'!$H$2:$H$73))+SUMPRODUCT(('Fase de Grupos'!$I$2:$I$73=$B17)*ISNUMBER('Fase de Grupos'!$F$2:$F$73)*ISNUMBER('Fase de Grupos'!$H$2:$H$73)*('Fase de Grupos'!$F$2:$F$73='Fase de Grupos'!$H$2:$H$73)) -> 1 | F17: =SUMPRODUCT(('Fase de Grupos'!$E$2:$E$73=$B17)*ISNUMBER('Fase de Grupos'!$F$2:$F$73)*ISNUMBER('Fase de Grupos'!$H$2:$H$73)*('Fase de Grupos'!$F$2:$F$73<'Fase de Grupos'!$H$2:$H$73))+SUMPRODUCT(('Fase de Grupos'!$I$2:$I$73=$B17)*ISNUMBER('Fase de Grupos'!$F$2:$F$73)*ISNUMBER('Fase de Grupos'!$H$2:$H$73)*('Fase de Grupos'!$H$2:$H$73<'Fase de Grupos'!$F$2:$F$73)) -> 0 | G17: =SUMPRODUCT(('Fase de Grupos'!$E$2:$E$73=$B17)*ISNUMBER('Fase de Grupos'!$F$2:$F$73)*ISNUMBER('Fase de Grupos'!$H$2:$H$73)*'Fase de Grupos'!$F$2:$F$73)+SUMPRODUCT(('Fase de Grupos'!$I$2:$I$73=$B17)*ISNUMBER('Fase de Grupos'!$F$2:$F$73)*ISNUMBER('Fase de Grupos'!$H$2:$H$73)*'Fase de Grupos'!$H$2:$H$73) -> 7 | H17: =SUMPRODUCT(('Fase de Grupos'!$E$2:$E$73=$B17)*ISNUMBER('Fase de Grupos'!$F$2:$F$73)*ISNUMBER('Fase de Grupos'!$H$2:$H$73)*'Fase de Grupos'!$H$2:$H$73)+SUMPRODUCT(('Fase de Grupos'!$I$2:$I$73=$B17)*ISNUMBER('Fase de Grupos'!$F$2:$F$73)*ISNUMBER('Fase de Grupos'!$H$2:$H$73)*'Fase de Grupos'!$F$2:$F$73) -> 1 | I17: =G17-H17 -> 6 | J17: =D17*3+E17 -> 7
A18: 2 | B18: Marrocos | C18: =SUMPRODUCT(('Fase de Grupos'!$E$2:$E$73=$B18)*ISNUMBER('Fase de Grupos'!$F$2:$F$73)*ISNUMBER('Fase de Grupos'!$H$2:$H$73))+SUMPRODUCT(('Fase de Grupos'!$I$2:$I$73=$B18)*ISNUMBER('Fase de Grupos'!$F$2:$F$73)*ISNUMBER('Fase de Grupos'!$H$2:$H$73)) -> 3 | D18: =SUMPRODUCT(('Fase de Grupos'!$E$2:$E$73=$B18)*ISNUMBER('Fase de Grupos'!$F$2:$F$73)*ISNUMBER('Fase de Grupos'!$H$2:$H$73)*('Fase de Grupos'!$F$2:$F$73>'Fase de Grupos'!$H$2:$H$73))+SUMPRODUCT(('Fase de Grupos'!$I$2:$I$73=$B18)*ISNUMBER('Fase de Grupos'!$F$2:$F$73)*ISNUMBER('Fase de Grupos'!$H$2:$H$73)*('Fase de Grupos'!$H$2:$H$73>'Fase de Grupos'!$F$2:$F$73)) -> 2 | E18: =SUMPRODUCT(('Fase de Grupos'!$E$2:$E$73=$B18)*ISNUMBER('Fase de Grupos'!$F$2:$F$73)*ISNUMBER('Fase de Grupos'!$H$2:$H$73)*('Fase de Grupos'!$F$2:$F$73='Fase de Grupos'!$H$2:$H$73))+SUMPRODUCT(('Fase de Grupos'!$I$2:$I$73=$B18)*ISNUMBER('Fase de Grupos'!$F$2:$F$73)*ISNUMBER('Fase de Grupos'!$H$2:$H$73)*('Fase de Grupos'!$F$2:$F$73='Fase de Grupos'!$H$2:$H$73)) -> 1 | F18: =SUMPRODUCT(('Fase de Grupos'!$E$2:$E$73=$B18)*ISNUMBER('Fase de Grupos'!$F$2:$F$73)*ISNUMBER('Fase de Grupos'!$H$2:$H$73)*('Fase de Grupos'!$F$2:$F$73<'Fase de Grupos'!$H$2:$H$73))+SUMPRODUCT(('Fase de Grupos'!$I$2:$I$73=$B18)*ISNUMBER('Fase de Grupos'!$F$2:$F$73)*ISNUMBER('Fase de Grupos'!$H$2:$H$73)*('Fase de Grupos'!$H$2:$H$73<'Fase de Grupos'!$F$2:$F$73)) -> 0 | G18: =SUMPRODUCT(('Fase de Grupos'!$E$2:$E$73=$B18)*ISNUMBER('Fase de Grupos'!$F$2:$F$73)*ISNUMBER('Fase de Grupos'!$H$2:$H$73)*'Fase de Grupos'!$F$2:$F$73)+SUMPRODUCT(('Fase de Grupos'!$I$2:$I$73=$B18)*ISNUMBER('Fase de Grupos'!$F$2:$F$73)*ISNUMBER('Fase de Grupos'!$H$2:$H$73)*'Fase de Grupos'!$H$2:$H$73) -> 6 | H18: =SUMPRODUCT(('Fase de Grupos'!$E$2:$E$73=$B18)*ISNUMBER('Fase de Grupos'!$F$2:$F$73)*ISNUMBER('Fase de Grupos'!$H$2:$H$73)*'Fase de Grupos'!$H$2:$H$73)+SUMPRODUCT(('Fase de Grupos'!$I$2:$I$73=$B18)*ISNUMBER('Fase de Grupos'!$F$2:$F$73)*ISNUMBER('Fase de Grupos'!$H$2:$H$73)*'Fase de Grupos'!$F$2:$F$73) -> 3 | I18: =G18-H18 -> 3 | J18: =D18*3+E18 -> 7
A19: 3 | B19: Haiti | C19: =SUMPRODUCT(('Fase de Grupos'!$E$2:$E$73=$B19)*ISNUMBER('Fase de Grupos'!$F$2:$F$73)*ISNUMBER('Fase de Grupos'!$H$2:$H$73))+SUMPRODUCT(('Fase de Grupos'!$I$2:$I$73=$B19)*ISNUMBER('Fase de Grupos'!$F$2:$F$73)*ISNUMBER('Fase de Grupos'!$H$2:$H$73)) -> 3 | D19: =SUMPRODUCT(('Fase de Grupos'!$E$2:$E$73=$B19)*ISNUMBER('Fase de Grupos'!$F$2:$F$73)*ISNUMBER('Fase de Grupos'!$H$2:$H$73)*('Fase de Grupos'!$F$2:$F$73>'Fase de Grupos'!$H$2:$H$73))+SUMPRODUCT(('Fase de Grupos'!$I$2:$I$73=$B19)*ISNUMBER('Fase de Grupos'!$F$2:$F$73)*ISNUMBER('Fase de Grupos'!$H$2:$H$73)*('Fase de Grupos'!$H$2:$H$73>'Fase de Grupos'!$F$2:$F$73)) -> 0 | E19: =SUMPRODUCT(('Fase de Grupos'!$E$2:$E$73=$B19)*ISNUMBER('Fase de Grupos'!$F$2:$F$73)*ISNUMBER('Fase de Grupos'!$H$2:$H$73)*('Fase de Grupos'!$F$2:$F$73='Fase de Grupos'!$H$2:$H$73))+SUMPRODUCT(('Fase de Grupos'!$I$2:$I$73=$B19)*ISNUMBER('Fase de Grupos'!$F$2:$F$73)*ISNUMBER('Fase de Grupos'!$H$2:$H$73)*('Fase de Grupos'!$F$2:$F$73='Fase de Grupos'!$H$2:$H$73)) -> 0 | F19: =SUMPRODUCT(('Fase de Grupos'!$E$2:$E$73=$B19)*ISNUMBER('Fase de Grupos'!$F$2:$F$73)*ISNUMBER('Fase de Grupos'!$H$2:$H$73)*('Fase de Grupos'!$F$2:$F$73<'Fase de Grupos'!$H$2:$H$73))+SUMPRODUCT(('Fase de Grupos'!$I$2:$I$73=$B19)*ISNUMBER('Fase de Grupos'!$F$2:$F$73)*ISNUMBER('Fase de Grupos'!$H$2:$H$73)*('Fase de Grupos'!$H$2:$H$73<'Fase de Grupos'!$F$2:$F$73)) -> 3 | G19: =SUMPRODUCT(('Fase de Grupos'!$E$2:$E$73=$B19)*ISNUMBER('Fase de Grupos'!$F$2:$F$73)*ISNUMBER('Fase de Grupos'!$H$2:$H$73)*'Fase de Grupos'!$F$2:$F$73)+SUMPRODUCT(('Fase de Grupos'!$I$2:$I$73=$B19)*ISNUMBER('Fase de Grupos'!$F$2:$F$73)*ISNUMBER('Fase de Grupos'!$H$2:$H$73)*'Fase de Grupos'!$H$2:$H$73) -> 2 | H19: =SUMPRODUCT(('Fase de Grupos'!$E$2:$E$73=$B19)*ISNUMBER('Fase de Grupos'!$F$2:$F$73)*ISNUMBER('Fase de Grupos'!$H$2:$H$73)*'Fase de Grupos'!$H$2:$H$73)+SUMPRODUCT(('Fase de Grupos'!$I$2:$I$73=$B19)*ISNUMBER('Fase de Grupos'!$F$2:$F$73)*ISNUMBER('Fase de Grupos'!$H$2:$H$73)*'Fase de Grupos'!$F$2:$F$73) -> 8 | I19: =G19-H19 -> -6 | J19: =D19*3+E19 -> 0
A20: 4 | B20: Escócia | C20: =SUMPRODUCT(('Fase de Grupos'!$E$2:$E$73=$B20)*ISNUMBER('Fase de Grupos'!$F$2:$F$73)*ISNUMBER('Fase de Grupos'!$H$2:$H$73))+SUMPRODUCT(('Fase de Grupos'!$I$2:$I$73=$B20)*ISNUMBER('Fase de Grupos'!$F$2:$F$73)*ISNUMBER('Fase de Grupos'!$H$2:$H$73)) -> 3 | D20: =SUMPRODUCT(('Fase de Grupos'!$E$2:$E$73=$B20)*ISNUMBER('Fase de Grupos'!$F$2:$F$73)*ISNUMBER('Fase de Grupos'!$H$2:$H$73)*('Fase de Grupos'!$F$2:$F$73>'Fase de Grupos'!$H$2:$H$73))+SUMPRODUCT(('Fase de Grupos'!$I$2:$I$73=$B20)*ISNUMBER('Fase de Grupos'!$F$2:$F$73)*ISNUMBER('Fase de Grupos'!$H$2:$H$73)*('Fase de Grupos'!$H$2:$H$73>'Fase de Grupos'!$F$2:$F$73)) -> 1 | E20: =SUMPRODUCT(('Fase de Grupos'!$E$2:$E$73=$B20)*ISNUMBER('Fase de Grupos'!$F$2:$F$73)*ISNUMBER('Fase de Grupos'!$H$2:$H$73)*('Fase de Grupos'!$F$2:$F$73='Fase de Grupos'!$H$2:$H$73))+SUMPRODUCT(('Fase de Grupos'!$I$2:$I$73=$B20)*ISNUMBER('Fase de Grupos'!$F$2:$F$73)*ISNUMBER('Fase de Grupos'!$H$2:$H$73)*('Fase de Grupos'!$F$2:$F$73='Fase de Grupos'!$H$2:$H$73)) -> 0 | F20: =SUMPRODUCT(('Fase de Grupos'!$E$2:$E$73=$B20)*ISNUMBER('Fase de Grupos'!$F$2:$F$73)*ISNUMBER('Fase de Grupos'!$H$2:$H$73)*('Fase de Grupos'!$F$2:$F$73<'Fase de Grupos'!$H$2:$H$73))+SUMPRODUCT(('Fase de Grupos'!$I$2:$I$73=$B20)*ISNUMBER('Fase de Grupos'!$F$2:$F$73)*ISNUMBER('Fase de Grupos'!$H$2:$H$73)*('Fase de Grupos'!$H$2:$H$73<'Fase de Grupos'!$F$2:$F$73)) -> 2 | G20: =SUMPRODUCT(('Fase de Grupos'!$E$2:$E$73=$B20)*ISNUMBER('Fase de Grupos'!$F$2:$F$73)*ISNUMBER('Fase de Grupos'!$H$2:$H$73)*'Fase de Grupos'!$F$2:$F$73)+SUMPRODUCT(('Fase de Grupos'!$I$2:$I$73=$B20)*ISNUMBER('Fase de Grupos'!$F$2:$F$73)*ISNUMBER('Fase de Grupos'!$H$2:$H$73)*'Fase de Grupos'!$H$2:$H$73) -> 1 | H20: =SUMPRODUCT(('Fase de Grupos'!$E$2:$E$73=$B20)*ISNUMBER('Fase de Grupos'!$F$2:$F$73)*ISNUMBER('Fase de Grupos'!$H$2:$H$73)*'Fase de Grupos'!$H$2:$H$73)+SUMPRODUCT(('Fase de Grupos'!$I$2:$I$73=$B20)*ISNUMBER('Fase de Grupos'!$F$2:$F$73)*ISNUMBER('Fase de Grupos'!$H$2:$H$73)*'Fase de Grupos'!$F$2:$F$73) -> 4 | I20: =G20-H20 -> -3 | J20: =D20*3+E20 -> 3
A22: Grupo D
A23: Pos | B23: Seleção | C23: J | D23: V | E23: E | F23: D | G23: GP | H23: GC | I23: SG | J23: PTS
A24: 1 | B24: EUA | C24: =SUMPRODUCT(('Fase de Grupos'!$E$2:$E$73=$B24)*ISNUMBER('Fase de Grupos'!$F$2:$F$73)*ISNUMBER('Fase de Grupos'!$H$2:$H$73))+SUMPRODUCT(('Fase de Grupos'!$I$2:$I$73=$B24)*ISNUMBER('Fase de Grupos'!$F$2:$F$73)*ISNUMBER('Fase de Grupos'!$H$2:$H$73)) -> 3 | D24: =SUMPRODUCT(('Fase de Grupos'!$E$2:$E$73=$B24)*ISNUMBER('Fase de Grupos'!$F$2:$F$73)*ISNUMBER('Fase de Grupos'!$H$2:$H$73)*('Fase de Grupos'!$F$2:$F$73>'Fase de Grupos'!$H$2:$H$73))+SUMPRODUCT(('Fase de Grupos'!$I$2:$I$73=$B24)*ISNUMBER('Fase de Grupos'!$F$2:$F$73)*ISNUMBER('Fase de Grupos'!$H$2:$H$73)*('Fase de Grupos'!$H$2:$H$73>'Fase de Grupos'!$F$2:$F$73)) -> 2 | E24: =SUMPRODUCT(('Fase de Grupos'!$E$2:$E$73=$B24)*ISNUMBER('Fase de Grupos'!$F$2:$F$73)*ISNUMBER('Fase de Grupos'!$H$2:$H$73)*('Fase de Grupos'!$F$2:$F$73='Fase de Grupos'!$H$2:$H$73))+SUMPRODUCT(('Fase de Grupos'!$I$2:$I$73=$B24)*ISNUMBER('Fase de Grupos'!$F$2:$F$73)*ISNUMBER('Fase de Grupos'!$H$2:$H$73)*('Fase de Grupos'!$F$2:$F$73='Fase de Grupos'!$H$2:$H$73)) -> 0 | F24: =SUMPRODUCT(('Fase de Grupos'!$E$2:$E$73=$B24)*ISNUMBER('Fase de Grupos'!$F$2:$F$73)*ISNUMBER('Fase de Grupos'!$H$2:$H$73)*('Fase de Grupos'!$F$2:$F$73<'Fase de Grupos'!$H$2:$H$73))+SUMPRODUCT(('Fase de Grupos'!$I$2:$I$73=$B24)*ISNUMBER('Fase de Grupos'!$F$2:$F$73)*ISNUMBER('Fase de Grupos'!$H$2:$H$73)*('Fase de Grupos'!$H$2:$H$73<'Fase de Grupos'!$F$2:$F$73)) -> 1 | G24: =SUMPRODUCT(('Fase de Grupos'!$E$2:$E$73=$B24)*ISNUMBER('Fase de Grupos'!$F$2:$F$73)*ISNUMBER('Fase de Grupos'!$H$2:$H$73)*'Fase de Grupos'!$F$2:$F$73)+SUMPRODUCT(('Fase de Grupos'!$I$2:$I$73=$B24)*ISNUMBER('Fase de Grupos'!$F$2:$F$73)*ISNUMBER('Fase de Grupos'!$H$2:$H$73)*'Fase de Grupos'!$H$2:$H$73) -> 8 | H24: =SUMPRODUCT(('Fase de Grupos'!$E$2:$E$73=$B24)*ISNUMBER('Fase de Grupos'!$F$2:$F$73)*ISNUMBER('Fase de Grupos'!$H$2:$H$73)*'Fase de Grupos'!$H$2:$H$73)+SUMPRODUCT(('Fase de Grupos'!$I$2:$I$73=$B24)*ISNUMBER('Fase de Grupos'!$F$2:$F$73)*ISNUMBER('Fase de Grupos'!$H$2:$H$73)*'Fase de Grupos'!$F$2:$F$73) -> 4 | I24: =G24-H24 -> 4 | J24: =D24*3+E24 -> 6
A25: 2 | B25: Paraguai | C25: =SUMPRODUCT(('Fase de Grupos'!$E$2:$E$73=$B25)*ISNUMBER('Fase de Grupos'!$F$2:$F$73)*ISNUMBER('Fase de Grupos'!$H$2:$H$73))+SUMPRODUCT(('Fase de Grupos'!$I$2:$I$73=$B25)*ISNUMBER('Fase de Grupos'!$F$2:$F$73)*ISNUMBER('Fase de Grupos'!$H$2:$H$73)) -> 3 | D25: =SUMPRODUCT(('Fase de Grupos'!$E$2:$E$73=$B25)*ISNUMBER('Fase de Grupos'!$F$2:$F$73)*ISNUMBER('Fase de Grupos'!$H$2:$H$73)*('Fase de Grupos'!$F$2:$F$73>'Fase de Grupos'!$H$2:$H$73))+SUMPRODUCT(('Fase de Grupos'!$I$2:$I$73=$B25)*ISNUMBER('Fase de Grupos'!$F$2:$F$73)*ISNUMBER('Fase de Grupos'!$H$2:$H$73)*('Fase de Grupos'!$H$2:$H$73>'Fase de Grupos'!$F$2:$F$73)) -> 1 | E25: =SUMPRODUCT(('Fase de Grupos'!$E$2:$E$73=$B25)*ISNUMBER('Fase de Grupos'!$F$2:$F$73)*ISNUMBER('Fase de Grupos'!$H$2:$H$73)*('Fase de Grupos'!$F$2:$F$73='Fase de Grupos'!$H$2:$H$73))+SUMPRODUCT(('Fase de Grupos'!$I$2:$I$73=$B25)*ISNUMBER('Fase de Grupos'!$F$2:$F$73)*ISNUMBER('Fase de Grupos'!$H$2:$H$73)*('Fase de Grupos'!$F$2:$F$73='Fase de Grupos'!$H$2:$H$73)) -> 1 | F25: =SUMPRODUCT(('Fase de Grupos'!$E$2:$E$73=$B25)*ISNUMBER('Fase de Grupos'!$F$2:$F$73)*ISNUMBER('Fase de Grupos'!$H$2:$H$73)*('Fase de Grupos'!$F$2:$F$73<'Fase de Grupos'!$H$2:$H$73))+SUMPRODUCT(('Fase de Grupos'!$I$2:$I$73=$B25)*ISNUMBER('Fase de Grupos'!$F$2:$F$73)*ISNUMBER('Fase de Grupos'!$H$2:$H$73)*('Fase de Grupos'!$H$2:$H$73<'Fase de Grupos'!$F$2:$F$73)) -> 1 | G25: =SUMPRODUCT(('Fase de Grupos'!$E$2:$E$73=$B25)*ISNUMBER('Fase de Grupos'!$F$2:$F$73)*ISNUMBER('Fase de Grupos'!$H$2:$H$73)*'Fase de Grupos'!$F$2:$F$73)+SUMPRODUCT(('Fase de Grupos'!$I$2:$I$73=$B25)*ISNUMBER('Fase de Grupos'!$F$2:$F$73)*ISNUMBER('Fase de Grupos'!$H$2:$H$73)*'Fase de Grupos'!$H$2:$H$73) -> 2 | H25: =SUMPRODUCT(('Fase de Grupos'!$E$2:$E$73=$B25)*ISNUMBER('Fase de Grupos'!$F$2:$F$73)*ISNUMBER('Fase de Grupos'!$H$2:$H$73)*'Fase de Grupos'!$H$2:$H$73)+SUMPRODUCT(('Fase de Grupos'!$I$2:$I$73=$B25)*ISNUMBER('Fase de Grupos'!$F$2:$F$73)*ISNUMBER('Fase de Grupos'!$H$2:$H$73)*'Fase de Grupos'!$F$2:$F$73) -> 4 | I25: =G25-H25 -> -2 | J25: =D25*3+E25 -> 4
A26: 3 | B26: Austrália | C26: =SUMPRODUCT(('Fase de Grupos'!$E$2:$E$73=$B26)*ISNUMBER('Fase de Grupos'!$F$2:$F$73)*ISNUMBER('Fase de Grupos'!$H$2:$H$73))+SUMPRODUCT(('Fase de Grupos'!$I$2:$I$73=$B26)*ISNUMBER('Fase de Grupos'!$F$2:$F$73)*ISNUMBER('Fase de Grupos'!$H$2:$H$73)) -> 3 | D26: =SUMPRODUCT(('Fase de Grupos'!$E$2:$E$73=$B26)*ISNUMBER('Fase de Grupos'!$F$2:$F$73)*ISNUMBER('Fase de Grupos'!$H$2:$H$73)*('Fase de Grupos'!$F$2:$F$73>'Fase de Grupos'!$H$2:$H$73))+SUMPRODUCT(('Fase de Grupos'!$I$2:$I$73=$B26)*ISNUMBER('Fase de Grupos'!$F$2:$F$73)*ISNUMBER('Fase de Grupos'!$H$2:$H$73)*('Fase de Grupos'!$H$2:$H$73>'Fase de Grupos'!$F$2:$F$73)) -> 1 | E26: =SUMPRODUCT(('Fase de Grupos'!$E$2:$E$73=$B26)*ISNUMBER('Fase de Grupos'!$F$2:$F$73)*ISNUMBER('Fase de Grupos'!$H$2:$H$73)*('Fase de Grupos'!$F$2:$F$73='Fase de Grupos'!$H$2:$H$73))+SUMPRODUCT(('Fase de Grupos'!$I$2:$I$73=$B26)*ISNUMBER('Fase de Grupos'!$F$2:$F$73)*ISNUMBER('Fase de Grupos'!$H$2:$H$73)*('Fase de Grupos'!$F$2:$F$73='Fase de Grupos'!$H$2:$H$73)) -> 1 | F26: =SUMPRODUCT(('Fase de Grupos'!$E$2:$E$73=$B26)*ISNUMBER('Fase de Grupos'!$F$2:$F$73)*ISNUMBER('Fase de Grupos'!$H$2:$H$73)*('Fase de Grupos'!$F$2:$F$73<'Fase de Grupos'!$H$2:$H$73))+SUMPRODUCT(('Fase de Grupos'!$I$2:$I$73=$B26)*ISNUMBER('Fase de Grupos'!$F$2:$F$73)*ISNUMBER('Fase de Grupos'!$H$2:$H$73)*('Fase de Grupos'!$H$2:$H$73<'Fase de Grupos'!$F$2:$F$73)) -> 1 | G26: =SUMPRODUCT(('Fase de Grupos'!$E$2:$E$73=$B26)*ISNUMBER('Fase de Grupos'!$F$2:$F$73)*ISNUMBER('Fase de Grupos'!$H$2:$H$73)*'Fase de Grupos'!$F$2:$F$73)+SUMPRODUCT(('Fase de Grupos'!$I$2:$I$73=$B26)*ISNUMBER('Fase de Grupos'!$F$2:$F$73)*ISNUMBER('Fase de Grupos'!$H$2:$H$73)*'Fase de Grupos'!$H$2:$H$73) -> 2 | H26: =SUMPRODUCT(('Fase de Grupos'!$E$2:$E$73=$B26)*ISNUMBER('Fase de Grupos'!$F$2:$F$73)*ISNUMBER('Fase de Grupos'!$H$2:$H$73)*'Fase de Grupos'!$H$2:$H$73)+SUMPRODUCT(('Fase de Grupos'!$I$2:$I$73=$B26)*ISNUMBER('Fase de Grupos'!$F$2:$F$73)*ISNUMBER('Fase de Grupos'!$H$2:$H$73)*'Fase de Grupos'!$F$2:$F$73) -> 2 | I26: =G26-H26 -> 0 | J26: =D26*3+E26 -> 4
A27: 4 | B27: Turquia | C27: =SUMPRODUCT(('Fase de Grupos'!$E$2:$E$73=$B27)*ISNUMBER('Fase de Grupos'!$F$2:$F$73)*ISNUMBER('Fase de Grupos'!$H$2:$H$73))+SUMPRODUCT(('Fase de Grupos'!$I$2:$I$73=$B27)*ISNUMBER('Fase de Grupos'!$F$2:$F$73)*ISNUMBER('Fase de Grupos'!$H$2:$H$73)) -> 3 | D27: =SUMPRODUCT(('Fase de Grupos'!$E$2:$E$73=$B27)*ISNUMBER('Fase de Grupos'!$F$2:$F$73)*ISNUMBER('Fase de Grupos'!$H$2:$H$73)*('Fase de Grupos'!$F$2:$F$73>'Fase de Grupos'!$H$2:$H$73))+SUMPRODUCT(('Fase de Grupos'!$I$2:$I$73=$B27)*ISNUMBER('Fase de Grupos'!$F$2:$F$73)*ISNUMBER('Fase de Grupos'!$H$2:$H$73)*('Fase de Grupos'!$H$2:$H$73>'Fase de Grupos'!$F$2:$F$73)) -> 1 | E27: =SUMPRODUCT(('Fase de Grupos'!$E$2:$E$73=$B27)*ISNUMBER('Fase de Grupos'!$F$2:$F$73)*ISNUMBER('Fase de Grupos'!$H$2:$H$73)*('Fase de Grupos'!$F$2:$F$73='Fase de Grupos'!$H$2:$H$73))+SUMPRODUCT(('Fase de Grupos'!$I$2:$I$73=$B27)*ISNUMBER('Fase de Grupos'!$F$2:$F$73)*ISNUMBER('Fase de Grupos'!$H$2:$H$73)*('Fase de Grupos'!$F$2:$F$73='Fase de Grupos'!$H$2:$H$73)) -> 0 | F27: =SUMPRODUCT(('Fase de Grupos'!$E$2:$E$73=$B27)*ISNUMBER('Fase de Grupos'!$F$2:$F$73)*ISNUMBER('Fase de Grupos'!$H$2:$H$73)*('Fase de Grupos'!$F$2:$F$73<'Fase de Grupos'!$H$2:$H$73))+SUMPRODUCT(('Fase de Grupos'!$I$2:$I$73=$B27)*ISNUMBER('Fase de Grupos'!$F$2:$F$73)*ISNUMBER('Fase de Grupos'!$H$2:$H$73)*('Fase de Grupos'!$H$2:$H$73<'Fase de Grupos'!$F$2:$F$73)) -> 2 | G27: =SUMPRODUCT(('Fase de Grupos'!$E$2:$E$73=$B27)*ISNUMBER('Fase de Grupos'!$F$2:$F$73)*ISNUMBER('Fase de Grupos'!$H$2:$H$73)*'Fase de Grupos'!$F$2:$F$73)+SUMPRODUCT(('Fase de Grupos'!$I$2:$I$73=$B27)*ISNUMBER('Fase de Grupos'!$F$2:$F$73)*ISNUMBER('Fase de Grupos'!$H$2:$H$73)*'Fase de Grupos'!$H$2:$H$73) -> 3 | H27: =SUMPRODUCT(('Fase de Grupos'!$E$2:$E$73=$B27)*ISNUMBER('Fase de Grupos'!$F$2:$F$73)*ISNUMBER('Fase de Grupos'!$H$2:$H$73)*'Fase de Grupos'!$H$2:$H$73)+SUMPRODUCT(('Fase de Grupos'!$I$2:$I$73=$B27)*ISNUMBER('Fase de Grupos'!$F$2:$F$73)*ISNUMBER('Fase de Grupos'!$H$2:$H$73)*'Fase de Grupos'!$F$2:$F$73) -> 5 | I27: =G27-H27 -> -2 | J27: =D27*3+E27 -> 3
A29: Grupo E
A30: Pos | B30: Seleção | C30: J | D30: V | E30: E | F30: D | G30: GP | H30: GC | I30: SG | J30: PTS
A31: 1 | B31: Alemanha | C31: =SUMPRODUCT(('Fase de Grupos'!$E$2:$E$73=$B31)*ISNUMBER('Fase de Grupos'!$F$2:$F$73)*ISNUMBER('Fase de Grupos'!$H$2:$H$73))+SUMPRODUCT(('Fase de Grupos'!$I$2:$I$73=$B31)*ISNUMBER('Fase de Grupos'!$F$2:$F$73)*ISNUMBER('Fase de Grupos'!$H$2:$H$73)) -> 3 | D31: =SUMPRODUCT(('Fase de Grupos'!$E$2:$E$73=$B31)*ISNUMBER('Fase de Grupos'!$F$2:$F$73)*ISNUMBER('Fase de Grupos'!$H$2:$H$73)*('Fase de Grupos'!$F$2:$F$73>'Fase de Grupos'!$H$2:$H$73))+SUMPRODUCT(('Fase de Grupos'!$I$2:$I$73=$B31)*ISNUMBER('Fase de Grupos'!$F$2:$F$73)*ISNUMBER('Fase de Grupos'!$H$2:$H$73)*('Fase de Grupos'!$H$2:$H$73>'Fase de Grupos'!$F$2:$F$73)) -> 2 | E31: =SUMPRODUCT(('Fase de Grupos'!$E$2:$E$73=$B31)*ISNUMBER('Fase de Grupos'!$F$2:$F$73)*ISNUMBER('Fase de Grupos'!$H$2:$H$73)*('Fase de Grupos'!$F$2:$F$73='Fase de Grupos'!$H$2:$H$73))+SUMPRODUCT(('Fase de Grupos'!$I$2:$I$73=$B31)*ISNUMBER('Fase de Grupos'!$F$2:$F$73)*ISNUMBER('Fase de Grupos'!$H$2:$H$73)*('Fase de Grupos'!$F$2:$F$73='Fase de Grupos'!$H$2:$H$73)) -> 0 | F31: =SUMPRODUCT(('Fase de Grupos'!$E$2:$E$73=$B31)*ISNUMBER('Fase de Grupos'!$F$2:$F$73)*ISNUMBER('Fase de Grupos'!$H$2:$H$73)*('Fase de Grupos'!$F$2:$F$73<'Fase de Grupos'!$H$2:$H$73))+SUMPRODUCT(('Fase de Grupos'!$I$2:$I$73=$B31)*ISNUMBER('Fase de Grupos'!$F$2:$F$73)*ISNUMBER('Fase de Grupos'!$H$2:$H$73)*('Fase de Grupos'!$H$2:$H$73<'Fase de Grupos'!$F$2:$F$73)) -> 1 | G31: =SUMPRODUCT(('Fase de Grupos'!$E$2:$E$73=$B31)*ISNUMBER('Fase de Grupos'!$F$2:$F$73)*ISNUMBER('Fase de Grupos'!$H$2:$H$73)*'Fase de Grupos'!$F$2:$F$73)+SUMPRODUCT(('Fase de Grupos'!$I$2:$I$73=$B31)*ISNUMBER('Fase de Grupos'!$F$2:$F$73)*ISNUMBER('Fase de Grupos'!$H$2:$H$73)*'Fase de Grupos'!$H$2:$H$73) -> 10 | H31: =SUMPRODUCT(('Fase de Grupos'!$E$2:$E$73=$B31)*ISNUMBER('Fase de Grupos'!$F$2:$F$73)*ISNUMBER('Fase de Grupos'!$H$2:$H$73)*'Fase de Grupos'!$H$2:$H$73)+SUMPRODUCT(('Fase de Grupos'!$I$2:$I$73=$B31)*ISNUMBER('Fase de Grupos'!$F$2:$F$73)*ISNUMBER('Fase de Grupos'!$H$2:$H$73)*'Fase de Grupos'!$F$2:$F$73) -> 4 | I31: =G31-H31 -> 6 | J31: =D31*3+E31 -> 6
A32: 2 | B32: Curaçao | C32: =SUMPRODUCT(('Fase de Grupos'!$E$2:$E$73=$B32)*ISNUMBER('Fase de Grupos'!$F$2:$F$73)*ISNUMBER('Fase de Grupos'!$H$2:$H$73))+SUMPRODUCT(('Fase de Grupos'!$I$2:$I$73=$B32)*ISNUMBER('Fase de Grupos'!$F$2:$F$73)*ISNUMBER('Fase de Grupos'!$H$2:$H$73)) -> 3 | D32: =SUMPRODUCT(('Fase de Grupos'!$E$2:$E$73=$B32)*ISNUMBER('Fase de Grupos'!$F$2:$F$73)*ISNUMBER('Fase de Grupos'!$H$2:$H$73)*('Fase de Grupos'!$F$2:$F$73>'Fase de Grupos'!$H$2:$H$73))+SUMPRODUCT(('Fase de Grupos'!$I$2:$I$73=$B32)*ISNUMBER('Fase de Grupos'!$F$2:$F$73)*ISNUMBER('Fase de Grupos'!$H$2:$H$73)*('Fase de Grupos'!$H$2:$H$73>'Fase de Grupos'!$F$2:$F$73)) -> 0 | E32: =SUMPRODUCT(('Fase de Grupos'!$E$2:$E$73=$B32)*ISNUMBER('Fase de Grupos'!$F$2:$F$73)*ISNUMBER('Fase de Grupos'!$H$2:$H$73)*('Fase de Grupos'!$F$2:$F$73='Fase de Grupos'!$H$2:$H$73))+SUMPRODUCT(('Fase de Grupos'!$I$2:$I$73=$B32)*ISNUMBER('Fase de Grupos'!$F$2:$F$73)*ISNUMBER('Fase de Grupos'!$H$2:$H$73)*('Fase de Grupos'!$F$2:$F$73='Fase de Grupos'!$H$2:$H$73)) -> 1 | F32: =SUMPRODUCT(('Fase de Grupos'!$E$2:$E$73=$B32)*ISNUMBER('Fase de Grupos'!$F$2:$F$73)*ISNUMBER('Fase de Grupos'!$H$2:$H$73)*('Fase de Grupos'!$F$2:$F$73<'Fase de Grupos'!$H$2:$H$73))+SUMPRODUCT(('Fase de Grupos'!$I$2:$I$73=$B32)*ISNUMBER('Fase de Grupos'!$F$2:$F$73)*ISNUMBER('Fase de Grupos'!$H$2:$H$73)*('Fase de Grupos'!$H$2:$H$73<'Fase de Grupos'!$F$2:$F$73)) -> 2 | G32: =SUMPRODUCT(('Fase de Grupos'!$E$2:$E$73=$B32)*ISNUMBER('Fase de Grupos'!$F$2:$F$73)*ISNUMBER('Fase de Grupos'!$H$2:$H$73)*'Fase de Grupos'!$F$2:$F$73)+SUMPRODUCT(('Fase de Grupos'!$I$2:$I$73=$B32)*ISNUMBER('Fase de Grupos'!$F$2:$F$73)*ISNUMBER('Fase de Grupos'!$H$2:$H$73)*'Fase de Grupos'!$H$2:$H$73) -> 1 | H32: =SUMPRODUCT(('Fase de Grupos'!$E$2:$E$73=$B32)*ISNUMBER('Fase de Grupos'!$F$2:$F$73)*ISNUMBER('Fase de Grupos'!$H$2:$H$73)*'Fase de Grupos'!$H$2:$H$73)+SUMPRODUCT(('Fase de Grupos'!$I$2:$I$73=$B32)*ISNUMBER('Fase de Grupos'!$F$2:$F$73)*ISNUMBER('Fase de Grupos'!$H$2:$H$73)*'Fase de Grupos'!$F$2:$F$73) -> 9 | I32: =G32-H32 -> -8 | J32: =D32*3+E32 -> 1
A33: 3 | B33: Costa do Marfim | C33: =SUMPRODUCT(('Fase de Grupos'!$E$2:$E$73=$B33)*ISNUMBER('Fase de Grupos'!$F$2:$F$73)*ISNUMBER('Fase de Grupos'!$H$2:$H$73))+SUMPRODUCT(('Fase de Grupos'!$I$2:$I$73=$B33)*ISNUMBER('Fase de Grupos'!$F$2:$F$73)*ISNUMBER('Fase de Grupos'!$H$2:$H$73)) -> 3 | D33: =SUMPRODUCT(('Fase de Grupos'!$E$2:$E$73=$B33)*ISNUMBER('Fase de Grupos'!$F$2:$F$73)*ISNUMBER('Fase de Grupos'!$H$2:$H$73)*('Fase de Grupos'!$F$2:$F$73>'Fase de Grupos'!$H$2:$H$73))+SUMPRODUCT(('Fase de Grupos'!$I$2:$I$73=$B33)*ISNUMBER('Fase de Grupos'!$F$2:$F$73)*ISNUMBER('Fase de Grupos'!$H$2:$H$73)*('Fase de Grupos'!$H$2:$H$73>'Fase de Grupos'!$F$2:$F$73)) -> 2 | E33: =SUMPRODUCT(('Fase de Grupos'!$E$2:$E$73=$B33)*ISNUMBER('Fase de Grupos'!$F$2:$F$73)*ISNUMBER('Fase de Grupos'!$H$2:$H$73)*('Fase de Grupos'!$F$2:$F$73='Fase de Grupos'!$H$2:$H$73))+SUMPRODUCT(('Fase de Grupos'!$I$2:$I$73=$B33)*ISNUMBER('Fase de Grupos'!$F$2:$F$73)*ISNUMBER('Fase de Grupos'!$H$2:$H$73)*('Fase de Grupos'!$F$2:$F$73='Fase de Grupos'!$H$2:$H$73)) -> 0 | F33: =SUMPRODUCT(('Fase de Grupos'!$E$2:$E$73=$B33)*ISNUMBER('Fase de Grupos'!$F$2:$F$73)*ISNUMBER('Fase de Grupos'!$H$2:$H$73)*('Fase de Grupos'!$F$2:$F$73<'Fase de Grupos'!$H$2:$H$73))+SUMPRODUCT(('Fase de Grupos'!$I$2:$I$73=$B33)*ISNUMBER('Fase de Grupos'!$F$2:$F$73)*ISNUMBER('Fase de Grupos'!$H$2:$H$73)*('Fase de Grupos'!$H$2:$H$73<'Fase de Grupos'!$F$2:$F$73)) -> 1 | G33: =SUMPRODUCT(('Fase de Grupos'!$E$2:$E$73=$B33)*ISNUMBER('Fase de Grupos'!$F$2:$F$73)*ISNUMBER('Fase de Grupos'!$H$2:$H$73)*'Fase de Grupos'!$F$2:$F$73)+SUMPRODUCT(('Fase de Grupos'!$I$2:$I$73=$B33)*ISNUMBER('Fase de Grupos'!$F$2:$F$73)*ISNUMBER('Fase de Grupos'!$H$2:$H$73)*'Fase de Grupos'!$H$2:$H$73) -> 4 | H33: =SUMPRODUCT(('Fase de Grupos'!$E$2:$E$73=$B33)*ISNUMBER('Fase de Grupos'!$F$2:$F$73)*ISNUMBER('Fase de Grupos'!$H$2:$H$73)*'Fase de Grupos'!$H$2:$H$73)+SUMPRODUCT(('Fase de Grupos'!$I$2:$I$73=$B33)*ISNUMBER('Fase de Grupos'!$F$2:$F$73)*ISNUMBER('Fase de Grupos'!$H$2:$H$73)*'Fase de Grupos'!$F$2:$F$73) -> 2 | I33: =G33-H33 -> 2 | J33: =D33*3+E33 -> 6
A34: 4 | B34: Equador | C34: =SUMPRODUCT(('Fase de Grupos'!$E$2:$E$73=$B34)*ISNUMBER('Fase de Grupos'!$F$2:$F$73)*ISNUMBER('Fase de Grupos'!$H$2:$H$73))+SUMPRODUCT(('Fase de Grupos'!$I$2:$I$73=$B34)*ISNUMBER('Fase de Grupos'!$F$2:$F$73)*ISNUMBER('Fase de Grupos'!$H$2:$H$73)) -> 3 | D34: =SUMPRODUCT(('Fase de Grupos'!$E$2:$E$73=$B34)*ISNUMBER('Fase de Grupos'!$F$2:$F$73)*ISNUMBER('Fase de Grupos'!$H$2:$H$73)*('Fase de Grupos'!$F$2:$F$73>'Fase de Grupos'!$H$2:$H$73))+SUMPRODUCT(('Fase de Grupos'!$I$2:$I$73=$B34)*ISNUMBER('Fase de Grupos'!$F$2:$F$73)*ISNUMBER('Fase de Grupos'!$H$2:$H$73)*('Fase de Grupos'!$H$2:$H$73>'Fase de Grupos'!$F$2:$F$73)) -> 1 | E34: =SUMPRODUCT(('Fase de Grupos'!$E$2:$E$73=$B34)*ISNUMBER('Fase de Grupos'!$F$2:$F$73)*ISNUMBER('Fase de Grupos'!$H$2:$H$73)*('Fase de Grupos'!$F$2:$F$73='Fase de Grupos'!$H$2:$H$73))+SUMPRODUCT(('Fase de Grupos'!$I$2:$I$73=$B34)*ISNUMBER('Fase de Grupos'!$F$2:$F$73)*ISNUMBER('Fase de Grupos'!$H$2:$H$73)*('Fase de Grupos'!$F$2:$F$73='Fase de Grupos'!$H$2:$H$73)) -> 1 | F34: =SUMPRODUCT(('Fase de Grupos'!$E$2:$E$73=$B34)*ISNUMBER('Fase de Grupos'!$F$2:$F$73)*ISNUMBER('Fase de Grupos'!$H$2:$H$73)*('Fase de Grupos'!$F$2:$F$73<'Fase de Grupos'!$H$2:$H$73))+SUMPRODUCT(('Fase de Grupos'!$I$2:$I$73=$B34)*ISNUMBER('Fase de Grupos'!$F$2:$F$73)*ISNUMBER('Fase de Grupos'!$H$2:$H$73)*('Fase de Grupos'!$H$2:$H$73<'Fase de Grupos'!$F$2:$F$73)) -> 1 | G34: =SUMPRODUCT(('Fase de Grupos'!$E$2:$E$73=$B34)*ISNUMBER('Fase de Grupos'!$F$2:$F$73)*ISNUMBER('Fase de Grupos'!$H$2:$H$73)*'Fase de Grupos'!$F$2:$F$73)+SUMPRODUCT(('Fase de Grupos'!$I$2:$I$73=$B34)*ISNUMBER('Fase de Grupos'!$F$2:$F$73)*ISNUMBER('Fase de Grupos'!$H$2:$H$73)*'Fase de Grupos'!$H$2:$H$73) -> 2 | H34: =SUMPRODUCT(('Fase de Grupos'!$E$2:$E$73=$B34)*ISNUMBER('Fase de Grupos'!$F$2:$F$73)*ISNUMBER('Fase de Grupos'!$H$2:$H$73)*'Fase de Grupos'!$H$2:$H$73)+SUMPRODUCT(('Fase de Grupos'!$I$2:$I$73=$B34)*ISNUMBER('Fase de Grupos'!$F$2:$F$73)*ISNUMBER('Fase de Grupos'!$H$2:$H$73)*'Fase de Grupos'!$F$2:$F$73) -> 2 | I34: =G34-H34 -> 0 | J34: =D34*3+E34 -> 4
A36: Grupo F
A37: Pos | B37: Seleção | C37: J | D37: V | E37: E | F37: D | G37: GP | H37: GC | I37: SG | J37: PTS
A38: 1 | B38: Holanda | C38: =SUMPRODUCT(('Fase de Grupos'!$E$2:$E$73=$B38)*ISNUMBER('Fase de Grupos'!$F$2:$F$73)*ISNUMBER('Fase de Grupos'!$H$2:$H$73))+SUMPRODUCT(('Fase de Grupos'!$I$2:$I$73=$B38)*ISNUMBER('Fase de Grupos'!$F$2:$F$73)*ISNUMBER('Fase de Grupos'!$H$2:$H$73)) -> 3 | D38: =SUMPRODUCT(('Fase de Grupos'!$E$2:$E$73=$B38)*ISNUMBER('Fase de Grupos'!$F$2:$F$73)*ISNUMBER('Fase de Grupos'!$H$2:$H$73)*('Fase de Grupos'!$F$2:$F$73>'Fase de Grupos'!$H$2:$H$73))+SUMPRODUCT(('Fase de Grupos'!$I$2:$I$73=$B38)*ISNUMBER('Fase de Grupos'!$F$2:$F$73)*ISNUMBER('Fase de Grupos'!$H$2:$H$73)*('Fase de Grupos'!$H$2:$H$73>'Fase de Grupos'!$F$2:$F$73)) -> 2 | E38: =SUMPRODUCT(('Fase de Grupos'!$E$2:$E$73=$B38)*ISNUMBER('Fase de Grupos'!$F$2:$F$73)*ISNUMBER('Fase de Grupos'!$H$2:$H$73)*('Fase de Grupos'!$F$2:$F$73='Fase de Grupos'!$H$2:$H$73))+SUMPRODUCT(('Fase de Grupos'!$I$2:$I$73=$B38)*ISNUMBER('Fase de Grupos'!$F$2:$F$73)*ISNUMBER('Fase de Grupos'!$H$2:$H$73)*('Fase de Grupos'!$F$2:$F$73='Fase de Grupos'!$H$2:$H$73)) -> 1 | F38: =SUMPRODUCT(('Fase de Grupos'!$E$2:$E$73=$B38)*ISNUMBER('Fase de Grupos'!$F$2:$F$73)*ISNUMBER('Fase de Grupos'!$H$2:$H$73)*('Fase de Grupos'!$F$2:$F$73<'Fase de Grupos'!$H$2:$H$73))+SUMPRODUCT(('Fase de Grupos'!$I$2:$I$73=$B38)*ISNUMBER('Fase de Grupos'!$F$2:$F$73)*ISNUMBER('Fase de Grupos'!$H$2:$H$73)*('Fase de Grupos'!$H$2:$H$73<'Fase de Grupos'!$F$2:$F$73)) -> 0 | G38: =SUMPRODUCT(('Fase de Grupos'!$E$2:$E$73=$B38)*ISNUMBER('Fase de Grupos'!$F$2:$F$73)*ISNUMBER('Fase de Grupos'!$H$2:$H$73)*'Fase de Grupos'!$F$2:$F$73)+SUMPRODUCT(('Fase de Grupos'!$I$2:$I$73=$B38)*ISNUMBER('Fase de Grupos'!$F$2:$F$73)*ISNUMBER('Fase de Grupos'!$H$2:$H$73)*'Fase de Grupos'!$H$2:$H$73) -> 10 | H38: =SUMPRODUCT(('Fase de Grupos'!$E$2:$E$73=$B38)*ISNUMBER('Fase de Grupos'!$F$2:$F$73)*ISNUMBER('Fase de Grupos'!$H$2:$H$73)*'Fase de Grupos'!$H$2:$H$73)+SUMPRODUCT(('Fase de Grupos'!$I$2:$I$73=$B38)*ISNUMBER('Fase de Grupos'!$F$2:$F$73)*ISNUMBER('Fase de Grupos'!$H$2:$H$73)*'Fase de Grupos'!$F$2:$F$73) -> 4 | I38: =G38-H38 -> 6 | J38: =D38*3+E38 -> 7
A39: 2 | B39: Japão | C39: =SUMPRODUCT(('Fase de Grupos'!$E$2:$E$73=$B39)*ISNUMBER('Fase de Grupos'!$F$2:$F$73)*ISNUMBER('Fase de Grupos'!$H$2:$H$73))+SUMPRODUCT(('Fase de Grupos'!$I$2:$I$73=$B39)*ISNUMBER('Fase de Grupos'!$F$2:$F$73)*ISNUMBER('Fase de Grupos'!$H$2:$H$73)) -> 3 | D39: =SUMPRODUCT(('Fase de Grupos'!$E$2:$E$73=$B39)*ISNUMBER('Fase de Grupos'!$F$2:$F$73)*ISNUMBER('Fase de Grupos'!$H$2:$H$73)*('Fase de Grupos'!$F$2:$F$73>'Fase de Grupos'!$H$2:$H$73))+SUMPRODUCT(('Fase de Grupos'!$I$2:$I$73=$B39)*ISNUMBER('Fase de Grupos'!$F$2:$F$73)*ISNUMBER('Fase de Grupos'!$H$2:$H$73)*('Fase de Grupos'!$H$2:$H$73>'Fase de Grupos'!$F$2:$F$73)) -> 1 | E39: =SUMPRODUCT(('Fase de Grupos'!$E$2:$E$73=$B39)*ISNUMBER('Fase de Grupos'!$F$2:$F$73)*ISNUMBER('Fase de Grupos'!$H$2:$H$73)*('Fase de Grupos'!$F$2:$F$73='Fase de Grupos'!$H$2:$H$73))+SUMPRODUCT(('Fase de Grupos'!$I$2:$I$73=$B39)*ISNUMBER('Fase de Grupos'!$F$2:$F$73)*ISNUMBER('Fase de Grupos'!$H$2:$H$73)*('Fase de Grupos'!$F$2:$F$73='Fase de Grupos'!$H$2:$H$73)) -> 2 | F39: =SUMPRODUCT(('Fase de Grupos'!$E$2:$E$73=$B39)*ISNUMBER('Fase de Grupos'!$F$2:$F$73)*ISNUMBER('Fase de Grupos'!$H$2:$H$73)*('Fase de Grupos'!$F$2:$F$73<'Fase de Grupos'!$H$2:$H$73))+SUMPRODUCT(('Fase de Grupos'!$I$2:$I$73=$B39)*ISNUMBER('Fase de Grupos'!$F$2:$F$73)*ISNUMBER('Fase de Grupos'!$H$2:$H$73)*('Fase de Grupos'!$H$2:$H$73<'Fase de Grupos'!$F$2:$F$73)) -> 0 | G39: =SUMPRODUCT(('Fase de Grupos'!$E$2:$E$73=$B39)*ISNUMBER('Fase de Grupos'!$F$2:$F$73)*ISNUMBER('Fase de Grupos'!$H$2:$H$73)*'Fase de Grupos'!$F$2:$F$73)+SUMPRODUCT(('Fase de Grupos'!$I$2:$I$73=$B39)*ISNUMBER('Fase de Grupos'!$F$2:$F$73)*ISNUMBER('Fase de Grupos'!$H$2:$H$73)*'Fase de Grupos'!$H$2:$H$73) -> 7 | H39: =SUMPRODUCT(('Fase de Grupos'!$E$2:$E$73=$B39)*ISNUMBER('Fase de Grupos'!$F$2:$F$73)*ISNUMBER('Fase de Grupos'!$H$2:$H$73)*'Fase de Grupos'!$H$2:$H$73)+SUMPRODUCT(('Fase de Grupos'!$I$2:$I$73=$B39)*ISNUMBER('Fase de Grupos'!$F$2:$F$73)*ISNUMBER('Fase de Grupos'!$H$2:$H$73)*'Fase de Grupos'!$F$2:$F$73) -> 3 | I39: =G39-H39 -> 4 | J39: =D39*3+E39 -> 5
A40: 3 | B40: Tunísia | C40: =SUMPRODUCT(('Fase de Grupos'!$E$2:$E$73=$B40)*ISNUMBER('Fase de Grupos'!$F$2:$F$73)*ISNUMBER('Fase de Grupos'!$H$2:$H$73))+SUMPRODUCT(('Fase de Grupos'!$I$2:$I$73=$B40)*ISNUMBER('Fase de Grupos'!$F$2:$F$73)*ISNUMBER('Fase de Grupos'!$H$2:$H$73)) -> 3 | D40: =SUMPRODUCT(('Fase de Grupos'!$E$2:$E$73=$B40)*ISNUMBER('Fase de Grupos'!$F$2:$F$73)*ISNUMBER('Fase de Grupos'!$H$2:$H$73)*('Fase de Grupos'!$F$2:$F$73>'Fase de Grupos'!$H$2:$H$73))+SUMPRODUCT(('Fase de Grupos'!$I$2:$I$73=$B40)*ISNUMBER('Fase de Grupos'!$F$2:$F$73)*ISNUMBER('Fase de Grupos'!$H$2:$H$73)*('Fase de Grupos'!$H$2:$H$73>'Fase de Grupos'!$F$2:$F$73)) -> 0 | E40: =SUMPRODUCT(('Fase de Grupos'!$E$2:$E$73=$B40)*ISNUMBER('Fase de Grupos'!$F$2:$F$73)*ISNUMBER('Fase de Grupos'!$H$2:$H$73)*('Fase de Grupos'!$F$2:$F$73='Fase de Grupos'!$H$2:$H$73))+SUMPRODUCT(('Fase de Grupos'!$I$2:$I$73=$B40)*ISNUMBER('Fase de Grupos'!$F$2:$F$73)*ISNUMBER('Fase de Grupos'!$H$2:$H$73)*('Fase de Grupos'!$F$2:$F$73='Fase de Grupos'!$H$2:$H$73)) -> 0 | F40: =SUMPRODUCT(('Fase de Grupos'!$E$2:$E$73=$B40)*ISNUMBER('Fase de Grupos'!$F$2:$F$73)*ISNUMBER('Fase de Grupos'!$H$2:$H$73)*('Fase de Grupos'!$F$2:$F$73<'Fase de Grupos'!$H$2:$H$73))+SUMPRODUCT(('Fase de Grupos'!$I$2:$I$73=$B40)*ISNUMBER('Fase de Grupos'!$F$2:$F$73)*ISNUMBER('Fase de Grupos'!$H$2:$H$73)*('Fase de Grupos'!$H$2:$H$73<'Fase de Grupos'!$F$2:$F$73)) -> 3 | G40: =SUMPRODUCT(('Fase de Grupos'!$E$2:$E$73=$B40)*ISNUMBER('Fase de Grupos'!$F$2:$F$73)*ISNUMBER('Fase de Grupos'!$H$2:$H$73)*'Fase de Grupos'!$F$2:$F$73)+SUMPRODUCT(('Fase de Grupos'!$I$2:$I$73=$B40)*ISNUMBER('Fase de Grupos'!$F$2:$F$73)*ISNUMBER('Fase de Grupos'!$H$2:$H$73)*'Fase de Grupos'!$H$2:$H$73) -> 2 | H40: =SUMPRODUCT(('Fase de Grupos'!$E$2:$E$73=$B40)*ISNUMBER('Fase de Grupos'!$F$2:$F$73)*ISNUMBER('Fase de Grupos'!$H$2:$H$73)*'Fase de Grupos'!$H$2:$H$73)+SUMPRODUCT(('Fase de Grupos'!$I$2:$I$73=$B40)*ISNUMBER('Fase de Grupos'!$F$2:$F$73)*ISNUMBER('Fase de Grupos'!$H$2:$H$73)*'Fase de Grupos'!$F$2:$F$73) -> 12 | I40: =G40-H40 -> -10 | J40: =D40*3+E40 -> 0
A41: 4 | B41: Suécia | C41: =SUMPRODUCT(('Fase de Grupos'!$E$2:$E$73=$B41)*ISNUMBER('Fase de Grupos'!$F$2:$F$73)*ISNUMBER('Fase de Grupos'!$H$2:$H$73))+SUMPRODUCT(('Fase de Grupos'!$I$2:$I$73=$B41)*ISNUMBER('Fase de Grupos'!$F$2:$F$73)*ISNUMBER('Fase de Grupos'!$H$2:$H$73)) -> 3 | D41: =SUMPRODUCT(('Fase de Grupos'!$E$2:$E$73=$B41)*ISNUMBER('Fase de Grupos'!$F$2:$F$73)*ISNUMBER('Fase de Grupos'!$H$2:$H$73)*('Fase de Grupos'!$F$2:$F$73>'Fase de Grupos'!$H$2:$H$73))+SUMPRODUCT(('Fase de Grupos'!$I$2:$I$73=$B41)*ISNUMBER('Fase de Grupos'!$F$2:$F$73)*ISNUMBER('Fase de Grupos'!$H$2:$H$73)*('Fase de Grupos'!$H$2:$H$73>'Fase de Grupos'!$F$2:$F$73)) -> 1 | E41: =SUMPRODUCT(('Fase de Grupos'!$E$2:$E$73=$B41)*ISNUMBER('Fase de Grupos'!$F$2:$F$73)*ISNUMBER('Fase de Grupos'!$H$2:$H$73)*('Fase de Grupos'!$F$2:$F$73='Fase de Grupos'!$H$2:$H$73))+SUMPRODUCT(('Fase de Grupos'!$I$2:$I$73=$B41)*ISNUMBER('Fase de Grupos'!$F$2:$F$73)*ISNUMBER('Fase de Grupos'!$H$2:$H$73)*('Fase de Grupos'!$F$2:$F$73='Fase de Grupos'!$H$2:$H$73)) -> 1 | F41: =SUMPRODUCT(('Fase de Grupos'!$E$2:$E$73=$B41)*ISNUMBER('Fase de Grupos'!$F$2:$F$73)*ISNUMBER('Fase de Grupos'!$H$2:$H$73)*('Fase de Grupos'!$F$2:$F$73<'Fase de Grupos'!$H$2:$H$73))+SUMPRODUCT(('Fase de Grupos'!$I$2:$I$73=$B41)*ISNUMBER('Fase de Grupos'!$F$2:$F$73)*ISNUMBER('Fase de Grupos'!$H$2:$H$73)*('Fase de Grupos'!$H$2:$H$73<'Fase de Grupos'!$F$2:$F$73)) -> 1 | G41: =SUMPRODUCT(('Fase de Grupos'!$E$2:$E$73=$B41)*ISNUMBER('Fase de Grupos'!$F$2:$F$73)*ISNUMBER('Fase de Grupos'!$H$2:$H$73)*'Fase de Grupos'!$F$2:$F$73)+SUMPRODUCT(('Fase de Grupos'!$I$2:$I$73=$B41)*ISNUMBER('Fase de Grupos'!$F$2:$F$73)*ISNUMBER('Fase de Grupos'!$H$2:$H$73)*'Fase de Grupos'!$H$2:$H$73) -> 7 | H41: =SUMPRODUCT(('Fase de Grupos'!$E$2:$E$73=$B41)*ISNUMBER('Fase de Grupos'!$F$2:$F$73)*ISNUMBER('Fase de Grupos'!$H$2:$H$73)*'Fase de Grupos'!$H$2:$H$73)+SUMPRODUCT(('Fase de Grupos'!$I$2:$I$73=$B41)*ISNUMBER('Fase de Grupos'!$F$2:$F$73)*ISNUMBER('Fase de Grupos'!$H$2:$H$73)*'Fase de Grupos'!$F$2:$F$73) -> 7 | I41: =G41-H41 -> 0 | J41: =D41*3+E41 -> 4
A43: Grupo G
A44: Pos | B44: Seleção | C44: J | D44: V | E44: E | F44: D | G44: GP | H44: GC | I44: SG | J44: PTS
A45: 1 | B45: Bélgica | C45: =SUMPRODUCT(('Fase de Grupos'!$E$2:$E$73=$B45)*ISNUMBER('Fase de Grupos'!$F$2:$F$73)*ISNUMBER('Fase de Grupos'!$H$2:$H$73))+SUMPRODUCT(('Fase de Grupos'!$I$2:$I$73=$B45)*ISNUMBER('Fase de Grupos'!$F$2:$F$73)*ISNUMBER('Fase de Grupos'!$H$2:$H$73)) -> 3 | D45: =SUMPRODUCT(('Fase de Grupos'!$E$2:$E$73=$B45)*ISNUMBER('Fase de Grupos'!$F$2:$F$73)*ISNUMBER('Fase de Grupos'!$H$2:$H$73)*('Fase de Grupos'!$F$2:$F$73>'Fase de Grupos'!$H$2:$H$73))+SUMPRODUCT(('Fase de Grupos'!$I$2:$I$73=$B45)*ISNUMBER('Fase de Grupos'!$F$2:$F$73)*ISNUMBER('Fase de Grupos'!$H$2:$H$73)*('Fase de Grupos'!$H$2:$H$73>'Fase de Grupos'!$F$2:$F$73)) -> 1 | E45: =SUMPRODUCT(('Fase de Grupos'!$E$2:$E$73=$B45)*ISNUMBER('Fase de Grupos'!$F$2:$F$73)*ISNUMBER('Fase de Grupos'!$H$2:$H$73)*('Fase de Grupos'!$F$2:$F$73='Fase de Grupos'!$H$2:$H$73))+SUMPRODUCT(('Fase de Grupos'!$I$2:$I$73=$B45)*ISNUMBER('Fase de Grupos'!$F$2:$F$73)*ISNUMBER('Fase de Grupos'!$H$2:$H$73)*('Fase de Grupos'!$F$2:$F$73='Fase de Grupos'!$H$2:$H$73)) -> 2 | F45: =SUMPRODUCT(('Fase de Grupos'!$E$2:$E$73=$B45)*ISNUMBER('Fase de Grupos'!$F$2:$F$73)*ISNUMBER('Fase de Grupos'!$H$2:$H$73)*('Fase de Grupos'!$F$2:$F$73<'Fase de Grupos'!$H$2:$H$73))+SUMPRODUCT(('Fase de Grupos'!$I$2:$I$73=$B45)*ISNUMBER('Fase de Grupos'!$F$2:$F$73)*ISNUMBER('Fase de Grupos'!$H$2:$H$73)*('Fase de Grupos'!$H$2:$H$73<'Fase de Grupos'!$F$2:$F$73)) -> 0 | G45: =SUMPRODUCT(('Fase de Grupos'!$E$2:$E$73=$B45)*ISNUMBER('Fase de Grupos'!$F$2:$F$73)*ISNUMBER('Fase de Grupos'!$H$2:$H$73)*'Fase de Grupos'!$F$2:$F$73)+SUMPRODUCT(('Fase de Grupos'!$I$2:$I$73=$B45)*ISNUMBER('Fase de Grupos'!$F$2:$F$73)*ISNUMBER('Fase de Grupos'!$H$2:$H$73)*'Fase de Grupos'!$H$2:$H$73) -> 6 | H45: =SUMPRODUCT(('Fase de Grupos'!$E$2:$E$73=$B45)*ISNUMBER('Fase de Grupos'!$F$2:$F$73)*ISNUMBER('Fase de Grupos'!$H$2:$H$73)*'Fase de Grupos'!$H$2:$H$73)+SUMPRODUCT(('Fase de Grupos'!$I$2:$I$73=$B45)*ISNUMBER('Fase de Grupos'!$F$2:$F$73)*ISNUMBER('Fase de Grupos'!$H$2:$H$73)*'Fase de Grupos'!$F$2:$F$73) -> 2 | I45: =G45-H45 -> 4 | J45: =D45*3+E45 -> 5
A46: 2 | B46: Egito | C46: =SUMPRODUCT(('Fase de Grupos'!$E$2:$E$73=$B46)*ISNUMBER('Fase de Grupos'!$F$2:$F$73)*ISNUMBER('Fase de Grupos'!$H$2:$H$73))+SUMPRODUCT(('Fase de Grupos'!$I$2:$I$73=$B46)*ISNUMBER('Fase de Grupos'!$F$2:$F$73)*ISNUMBER('Fase de Grupos'!$H$2:$H$73)) -> 3 | D46: =SUMPRODUCT(('Fase de Grupos'!$E$2:$E$73=$B46)*ISNUMBER('Fase de Grupos'!$F$2:$F$73)*ISNUMBER('Fase de Grupos'!$H$2:$H$73)*('Fase de Grupos'!$F$2:$F$73>'Fase de Grupos'!$H$2:$H$73))+SUMPRODUCT(('Fase de Grupos'!$I$2:$I$73=$B46)*ISNUMBER('Fase de Grupos'!$F$2:$F$73)*ISNUMBER('Fase de Grupos'!$H$2:$H$73)*('Fase de Grupos'!$H$2:$H$73>'Fase de Grupos'!$F$2:$F$73)) -> 1 | E46: =SUMPRODUCT(('Fase de Grupos'!$E$2:$E$73=$B46)*ISNUMBER('Fase de Grupos'!$F$2:$F$73)*ISNUMBER('Fase de Grupos'!$H$2:$H$73)*('Fase de Grupos'!$F$2:$F$73='Fase de Grupos'!$H$2:$H$73))+SUMPRODUCT(('Fase de Grupos'!$I$2:$I$73=$B46)*ISNUMBER('Fase de Grupos'!$F$2:$F$73)*ISNUMBER('Fase de Grupos'!$H$2:$H$73)*('Fase de Grupos'!$F$2:$F$73='Fase de Grupos'!$H$2:$H$73)) -> 2 | F46: =SUMPRODUCT(('Fase de Grupos'!$E$2:$E$73=$B46)*ISNUMBER('Fase de Grupos'!$F$2:$F$73)*ISNUMBER('Fase de Grupos'!$H$2:$H$73)*('Fase de Grupos'!$F$2:$F$73<'Fase de Grupos'!$H$2:$H$73))+SUMPRODUCT(('Fase de Grupos'!$I$2:$I$73=$B46)*ISNUMBER('Fase de Grupos'!$F$2:$F$73)*ISNUMBER('Fase de Grupos'!$H$2:$H$73)*('Fase de Grupos'!$H$2:$H$73<'Fase de Grupos'!$F$2:$F$73)) -> 0 | G46: =SUMPRODUCT(('Fase de Grupos'!$E$2:$E$73=$B46)*ISNUMBER('Fase de Grupos'!$F$2:$F$73)*ISNUMBER('Fase de Grupos'!$H$2:$H$73)*'Fase de Grupos'!$F$2:$F$73)+SUMPRODUCT(('Fase de Grupos'!$I$2:$I$73=$B46)*ISNUMBER('Fase de Grupos'!$F$2:$F$73)*ISNUMBER('Fase de Grupos'!$H$2:$H$73)*'Fase de Grupos'!$H$2:$H$73) -> 5 | H46: =SUMPRODUCT(('Fase de Grupos'!$E$2:$E$73=$B46)*ISNUMBER('Fase de Grupos'!$F$2:$F$73)*ISNUMBER('Fase de Grupos'!$H$2:$H$73)*'Fase de Grupos'!$H$2:$H$73)+SUMPRODUCT(('Fase de Grupos'!$I$2:$I$73=$B46)*ISNUMBER('Fase de Grupos'!$F$2:$F$73)*ISNUMBER('Fase de Grupos'!$H$2:$H$73)*'Fase de Grupos'!$F$2:$F$73) -> 3 | I46: =G46-H46 -> 2 | J46: =D46*3+E46 -> 5
...

Sheet Mata-Mata
A1: Jogo # | B1: Fase | C1: Data | D1: Seleção 1 | E1: Gols 1 | F1: x | G1: Gols 2 | H1: Seleção 2 | I1: Cidade/Estádio | J1: Horário (BRT)
A2: 73 | B2: 16 avos | C2: 28/06 | D2: Àfrica do Sul | E2: 0 | F2: x | G2: 1 | H2: Canadá | I2: Los Angeles | J2: 0.66666667
A3: 74 | B3: 16 avos | C3: 29/06 | D3: Brasil | F3: x | H3: Japão | I3: Boston | J3: 0.58333333
A4: 75 | B4: 16 avos | C4: 29/06 | D4: Alemanha | F4: x | H4: Paraguai | I4: Monterrey | J4: 0.72916667
A5: 76 | B5: 16 avos | C5: 29/06 | D5: Holanda | F5: x | H5: Marrocos | I5: Houston | J5: 0.91666667
A6: 77 | B6: 16 avos | C6: 30/06 | D6: Costa do Marfim | F6: x | H6: Noruega | I6: Nova York/NJ | J6: 0.58333333
A7: 78 | B7: 16 avos | C7: 30/06 | D7: França | F7: x | H7: Suécia | I7: Dallas | J7: 0.75
A8: 79 | B8: 16 avos | C8: 30/06 | D8: México | F8: x | H8: Equador | I8: Cidade do México | J8: 0.91666667
A9: 80 | B9: 16 avos | C9: 01/07 | D9: Inglaterra | F9: x | H9: Congo | I9: Atlanta | J9: 0.54166667
A10: 81 | B10: 16 avos | C10: 01/07 | D10: Bélgica | F10: x | H10: Senegal | I10: San Francisco | J10: 0.70833333
A11: 82 | B11: 16 avos | C11: 01/07 | D11: Estados Unidos | F11: x | H11: Bósnia Herzegovina | I11: Seattle | J11: 0.875
A12: 83 | B12: 16 avos | C12: 02/07 | D12: Espanha | F12: x | H12: Áustria | I12: Toronto | J12: 0.66666667
A13: 84 | B13: 16 avos | C13: 02/07 | D13: Portugal | F13: x | H13: Croácia | I13: Los Angeles | J13: 0.83333333
A14: 85 | B14: 16 avos | C14: 03/07 | D14: Suíça | F14: x | H14: Argélia | I14: Vancouver | J14: 0
... A17: 88 | B17: 16 avos | C17: 03/07 | D17: Colômbia | F17: x | H17: Gana | I17: Dallas | J17: 0.9375
A18: 89 | B18: Oitavas | C18: 04/07 | D18: A definir | F18: x | H18: A definir | I18: Filadélfia
A19: 90 | B19: Oitavas | C19: 04/07 | D19: A definir | F19: x | H19: A definir | I19: Houston
A20: 91 | B20: Oitavas | C20: 05/07 | D20: A definir | F20: x | H20: A definir | I20: Nova York/NJ
A21: 92 | B21: Oitavas | C21: 05/07 | D21: A definir | F21: x | H21: A definir | I21: Cidade do México
A22: 93 | B22: Oitavas | C22: 06/07 | D22: A definir | F22: x | H22: A definir | I22: Dallas
A23: 94 | B23: Oitavas | C23: 06/07 | D23: A definir | F23: x | H23: A definir | I23: Seattle
A24: 95 | B24: Oitavas | C24: 07/07 | D24: A definir | F24: x | H24: A definir | I24: Atlanta
A25: 96 | B25: Oitavas | C25: 07/07 | D25: A definir | F25: x | H25: A definir | I25: Vancouver
A26: 97 | B26: Quartas | C26: 09/07 | D26: A definir | F26: x | H26: A definir | I26: Boston
A27: 98 | B27: Quartas | C27: 10/07 | D27: A definir | F27: x | H27: A definir | I27: Los Angeles
A28: 99 | B28: Quartas | C28: 11/07 | D28: A definir | F28: x | H28: A definir | I28: Miami
A29: 100 | B29: Quartas | C29: 11/07 | D29: A definir | F29: x | H29: A definir | I29: Kansas City
... A33: 104 | B33: FINAL | C33: 19/07 | D33: A definir | F33: x | H33: A definir | I33: Nova York/NJ

Sheet Palpites - Cosman
A1: Jogo # | B1: Data | C1: Grupo | D1: Seleção 1 | E1: Palpite 1 | F1: x | G1: Palpite 2 | H1: Seleção 2 | I1: Resultado | J1: Pontos
